Workbook

Sheet Read Me
A1: gammaCore for Chronic Cluster Headache — Cost-Effectiveness (Cost-Minimisation) Model
A3: Replication of the electroCore sponsor submission to NICE, Medical Technology Guidance MT323 ("Supporting documentation – Committee papers"), Section 9 De novo cost analysis, cross-checked against the External Assessment Centre (EAC) report, Section 4.6.
A6: Model overview
A7: This is a 2-state Markov cost-minimisation model (no QALYs — the sponsor did not model health utilities, only NHS resource costs). States are Responder and Non-responder, defined as achieving a threshold reduction in weekly cluster-headache attack frequency vs. baseline. Two arms are compared: gammaCore (nVNS) added to standard-of-care abortive medication, vs. standard of care (SoC) alone. Cycle length is 1 month, time horizon is 12 months, perspective is NHS, and no discounting is applied (consistent with the sponsor's Table C9).
A8: Costs comprise abortive medication (zolmitriptan nasal spray, subcutaneous/nasal sumatriptan, and inhaled oxygen) plus the gammaCore device itself (£625 per 93-day/3-month refill card, with the first 3 months supplied free). All clinical and resource-use parameters are taken from Tables C10–C15 of the sponsor submission.
A10: Sheet guide
A11: • Inputs — every hardcoded parameter (blue font), including the dose table for all five responder definitions (≥25%, ≥40%, ≥50%, ≥65%, and the Morris et al. 2016 "50% using means" approach), unit costs, and four yellow scenario-selector cells that drive the Model sheet.
A12: • Model — a live, fully-formula-driven 12-month trace for the scenario currently selected on the Inputs sheet. Change the yellow selector cells and this sheet (and Results) recalculate automatically.
A13: • Results — headline totals and a cost-by-category breakdown for the current scenario, shown alongside the company's own published figures (Table C16–C18) for direct comparison.
A14: • Scenarios — all 30 combinations of responder definition (5) × response-loss assumption (3) × non-responder use assumption (2) pre-computed side-by-side, reproducing the structure of Table C20. A summary table at the top links to a full 12-month calculation block for each scenario below.
A15: • OWSA — one-way deterministic sensitivity analysis on the ten parameters with the largest impact (cf. Table C19 / the tornado diagram), each varied independently to its published lower/upper bound.
A17: Validation against the published results
... A28: electroCore. Supporting documentation – Committee papers: gammaCore for cluster headache [MT323]. Sponsor submission of evidence, Section 9 (pp. 132–177); and NICE External Assessment Centre report, Section 4.6 (pp. 62–74). Companion R script available on request.

Sheet Inputs
A1: gammaCore for Chronic Cluster Headache — Model INPUTS
A2: All hardcoded inputs (blue) sourced from the electroCore sponsor submission to NICE, Section 9 (Tables C10–C15), unless noted.
A4: 1. UNIT COSTS (NHS Drug Tariff, March 2019 / East of England Priorities Advisory Committee, 2017)
A5: Zolmitriptan nasal — cost per unit (£) | B5: 6.08 | D5: Table C10
A6: Sumatriptan s.c. — cost per unit (£) | B6: 19.75 | D6: Table C10
A7: Sumatriptan nasal — cost per unit (£) | B7: 7.08 | D7: Table C10
A8: Oxygen (static cylinder) — cost per treatment (£) | B8: 0.56 | D8: Table C10; range 0.50–0.63
A9: Oxygen (portable cylinder) — cost per treatment (£) | B9: 0.79 | D9: Table C10; range 0.70–0.88
A10: % of sumatriptan treatments that are s.c. | B10: 0.867 | D10: Table C10; range 66.1%–98.2%
A11: % of oxygen treatments that are portable | B11: 0.5 | D11: Table C10; range 0%–60% (assumption)
A12: Blended sumatriptan unit cost (£) — derived | B12: =B10*B6+(1-B10)*B7 -> 18.06489
A13: Blended oxygen unit cost (£) — derived | B13: =B11*B9+(1-B11)*B8 -> 0.675
A15: 2. GAMMACORE DEVICE PRICING
A16: gammaCore cost per 93-day (3-month) refill (£, ex. VAT) | B16: 625 | D16: Section 9.3.5 — list price
A17: Number of free initial months (activation card) | B17: 3 | D17: Section 9.1.5
A18: Smoothed monthly equivalent cost (£) — derived | B18: =B16/3 -> 208.33333
A20: 3. RESPONSE PROBABILITIES
A21: Probability of response (≥50%) — SoC, month 1 | B21: 0.083 | D21: Table C10; Gaul et al. 2016; range 2.4%–17.5%
A22: Probability of discontinued response per month — initial gCore responders | B22: 0.31 | D22: Table C10; range 16.2%–54.1%
A24: 4. TIME CONVERSION
A25: Average days per month (365.25/12) — converts doses/14 days to doses/month | B25: =365.25/12 -> 30.4375
A27: 5. DOSE TABLE BY RESPONDER DEFINITION (doses per 14 days; Table C10)
A28: Definition | B28: P(response) gCore | C28: Responder zolm | D28: Responder suma | E28: Responder oxy | F28: Non-resp (on Tx) zolm | G28: Non-resp (on Tx) suma | H28: Non-resp (on Tx) oxy | I28: Non-resp (baseline) zolm | J28: Non-resp (baseline) suma | K28: Non-resp (baseline) oxy
A29: 25 | B29: 0.6 | C29: 0.8 | D29: 2.5 | E29: 3.5 | F29: 3.8 | G29: 5.8 | H29: 16.2 | I29: 4.8 | J29: 3.8 | K29: 16.3
A30: 40 | B30: 0.47 | C30: 1 | D30: 3 | E30: 2.8 | F30: 2.5 | G30: 3.7 | H30: 12.2 | I30: 3.3 | J30: 2.9 | K30: 19.3
A31: 50 | B31: 0.4 | C31: 0.6 | D31: 2.5 | E31: 2.2 | F31: 2.5 | G31: 4.1 | H31: 11.2 | I31: 3.8 | J31: 4.5 | K31: 18.6
A32: 65 | B32: 0.24 | C32: 0 | D32: 2 | E32: 0.7 | F32: 2.2 | G32: 3.8 | H32: 9.2 | I32: 3.8 | J32: 5 | K32: 31
A33: 50m | B33: 0.4 | C33: 1.6 | D33: 2.8 | E33: 6.5 | F33: 1.3 | G33: 7.5 | H33: 10.8 | I33: 1.3 | J33: 7.5 | K33: 10.8
A35: 6. STANDARD-OF-CARE NON-RESPONDER DOSE (fixed, doses per 14 days; Table C10)
A36: zolm | B36: suma | C36: oxy
A37: 1.3 | B37: 7.5 | C37: 10.8
A39: 7. SCENARIO SELECTORS (drive the Model sheet — change these to explore scenarios)
A40: Responder definition | B40: 50 | D40: Choose: 25 / 40 / 50 / 65 / 50m
A41: Response-loss assumption | B41: none | D41: Choose: none / constant / diminishing
A42: Non-responder use assumption (post-discontinuation) | B42: soc | D42: Choose: soc / baseline
A43: SoC arm: no initial response scenario? | B43: No | D43: Choose: Yes / No

Sheet Model
A1: gammaCore for Chronic Cluster Headache — MODEL (12-month Markov trace)
A2: Driven by the scenario selectors on the Inputs sheet. All formulas recalculate automatically when those selectors change.
A4: Selected responder definition: | B4: =Inputs!$B$40 -> 50 | D4: P(response) gCore: | E4: =VLOOKUP(Inputs!$B$40,Inputs!$A$29:$K$33,2,FALSE()) -> 0.4
A5: Response-loss assumption: | B5: =Inputs!$B$41 -> none | D5: P(discontinued response)/month: | E5: =Inputs!$B$22 -> 0.31
A6: Non-responder use (post-discontinuation): | B6: =Inputs!$B$42 -> soc | D6: SoC — no initial response scenario: | E6: =Inputs!$B$43 -> No
A8: Cycle | B8: In free trial? | C8: gCore arm responder % | D8: gCore arm monthly cost (£) | E8: SoC arm responder % | F8: SoC arm monthly cost (£)
A9: 1 | B9: =A9<=Inputs!$B$17 -> TRUE | C9: =VLOOKUP(Inputs!$B$40,Inputs!$A$29:$K$33,2,FALSE()) -> 0.4 | D9: =IF(B9,C9*(VLOOKUP(Inputs!$B$40,Inputs!$A$29:$K$33,3,FALSE())*(Inputs!$B$25/14)*Inputs!$B$5+VLOOKUP(Inputs!$B$40,Inputs!$A$29:$K$33,4,FALSE())*(Inputs!$B$25/14)*Inputs!$B$12+VLOOKUP(Inputs!$B$40,Inputs!$A$29:$K$33,5,FALSE())*(Inputs!$B$25/14)*Inputs!$B$13)+(1-C9)*(VLOOKUP(Inputs!$B$40,Inputs!$A$29:$K$33,6,FALSE())*(Inputs!$B$25/14)*Inputs!$B$5+VLOOKUP(Inputs!$B$40,Inputs!$A$29:$K$33,7,FALSE())*(Inputs!$B$25/14)*Inputs!$B$12+VLOOKUP(Inputs!$B$40,Inputs!$A$29:$K$33,8,FALSE())*(Inputs!$B$25/14)*Inputs!$B$13),C9*((VLOOKUP(Inputs!$B$40,Inputs!$A$29:$K$33,3,FALSE())*(Inputs!$B$25/14)*Inputs!$B$5+VLOOKUP(Inputs!$B$40,Inputs!$A$29:$K$33,4,FALSE())*(Inputs!$B$25/14)*Inputs!$B$12+VLOOKUP(Inputs!$B$40,Inputs!$A$29:$K$33,5,FALSE())*(Inputs!$B$25/14)*Inputs!$B$13)+Inputs!$B$18)+(1-C9)*IF(Inputs!$B$42="soc",(INDEX(Inputs!$A$37:$C$37,1,1)*(Inputs!$B$25/14)*Inputs!$B$5+INDEX(Inputs!$A$37:$C$37,1,2)*(Inputs!$B$25/14)*Inputs!$B$12+INDEX(Inputs!$A$37:$C$37,1,3)*(Inputs!$B$25/14)*Inputs!$B$13),(VLOOKUP(Inputs!$B$40,Inputs!$A$29:$K$33,9,FALSE())*(Inputs!$B$25/14)*Inputs!$B$5+VLOOKUP(Inputs!$B$40,Inputs!$A$29:$K$33,10,FALSE())*(Inputs!$B$25/14)*Inputs!$B$12+VLOOKUP(Inputs!$B$40,Inputs!$A$29:$K$33,11,FALSE())*(Inputs!$B$25/14)*Inputs!$B$13))) -> 170.04501 | E9: =IF(Inputs!$B$43="Yes",0,Inputs!$B$21) -> 0.083 | F9: =E9*(VLOOKUP(Inputs!$B$40,Inputs!$A$29:$K$33,3,FALSE())*(Inputs!$B$25/14)*Inputs!$B$5+VLOOKUP(Inputs!$B$40,Inputs!$A$29:$K$33,4,FALSE())*(Inputs!$B$25/14)*Inputs!$B$12+VLOOKUP(Inputs!$B$40,Inputs!$A$29:$K$33,5,FALSE())*(Inputs!$B$25/14)*Inputs!$B$13)+(1-E9)*(INDEX(Inputs!$A$37:$C$37,1,1)*(Inputs!$B$25/14)*Inputs!$B$5+INDEX(Inputs!$A$37:$C$37,1,2)*(Inputs!$B$25/14)*Inputs!$B$12+INDEX(Inputs!$A$37:$C$37,1,3)*(Inputs!$B$25/14)*Inputs!$B$13) -> 309.48129
A10: 2 | B10: =A10<=Inputs!$B$17 -> TRUE | C10: =IF(Inputs!$B$41="none",IF(A10=2,C9*(1-Inputs!$B$22),C9),IF(Inputs!$B$41="constant",C9*(1-Inputs!$B$22),C9*(1-Inputs!$B$22*(0.9^(A10-2))))) -> 0.276 | D10: =IF(B10,C10*(VLOOKUP(Inputs!$B$40,Inputs!$A$29:$K$33,3,FALSE())*(Inputs!$B$25/14)*Inputs!$B$5+VLOOKUP(Inputs!$B$40,Inputs!$A$29:$K$33,4,FALSE())*(Inputs!$B$25/14)*Inputs!$B$12+VLOOKUP(Inputs!$B$40,Inputs!$A$29:$K$33,5,FALSE())*(Inputs!$B$25/14)*Inputs!$B$13)+(1-C10)*(VLOOKUP(Inputs!$B$40,Inputs!$A$29:$K$33,6,FALSE())*(Inputs!$B$25/14)*Inputs!$B$5+VLOOKUP(Inputs!$B$40,Inputs!$A$29:$K$33,7,FALSE())*(Inputs!$B$25/14)*Inputs!$B$12+VLOOKUP(Inputs!$B$40,Inputs!$A$29:$K$33,8,FALSE())*(Inputs!$B$25/14)*Inputs!$B$13),C10*((VLOOKUP(Inputs!$B$40,Inputs!$A$29:$K$33,3,FALSE())*(Inputs!$B$25/14)*Inputs!$B$5+VLOOKUP(Inputs!$B$40,Inputs!$A$29:$K$33,4,FALSE())*(Inputs!$B$25/14)*Inputs!$B$12+VLOOKUP(Inputs!$B$40,Inputs!$A$29:$K$33,5,FALSE())*(Inputs!$B$25/14)*Inputs!$B$13)+Inputs!$B$18)+(1-C10)*IF(Inputs!$B$42="soc",(INDEX(Inputs!$A$37:$C$37,1,1)*(Inputs!$B$25/14)*Inputs!$B$5+INDEX(Inputs!$A$37:$C$37,1,2)*(Inputs!$B$25/14)*Inputs!$B$12+INDEX(Inputs!$A$37:$C$37,1,3)*(Inputs!$B$25/14)*Inputs!$B$13),(VLOOKUP(Inputs!$B$40,Inputs!$A$29:$K$33,9,FALSE())*(Inputs!$B$25/14)*Inputs!$B$5+VLOOKUP(Inputs!$B$40,Inputs!$A$29:$K$33,10,FALSE())*(Inputs!$B$25/14)*Inputs!$B$12+VLOOKUP(Inputs!$B$40,Inputs!$A$29:$K$33,11,FALSE())*(Inputs!$B$25/14)*Inputs!$B$13))) -> 182.58922 | E10: =0 -> 0 | F10: =(INDEX(Inputs!$A$37:$C$37,1,1)*(Inputs!$B$25/14)*Inputs!$B$5+INDEX(Inputs!$A$37:$C$37,1,2)*(Inputs!$B$25/14)*Inputs!$B$12+INDEX(Inputs!$A$37:$C$37,1,3)*(Inputs!$B$25/14)*Inputs!$B$13) -> 327.59593
A11: 3 | B11: =A11<=Inputs!$B$17 -> TRUE | C11: =IF(Inputs!$B$41="none",IF(A11=2,C10*(1-Inputs!$B$22),C10),IF(Inputs!$B$41="constant",C10*(1-Inputs!$B$22),C10*(1-Inputs!$B$22*(0.9^(A11-2))))) -> 0.276 | D11: =IF(B11,C11*(VLOOKUP(Inputs!$B$40,Inputs!$A$29:$K$33,3,FALSE())*(Inputs!$B$25/14)*Inputs!$B$5+VLOOKUP(Inputs!$B$40,Inputs!$A$29:$K$33,4,FALSE())*(Inputs!$B$25/14)*Inputs!$B$12+VLOOKUP(Inputs!$B$40,Inputs!$A$29:$K$33,5,FALSE())*(Inputs!$B$25/14)*Inputs!$B$13)+(1-C11)*(VLOOKUP(Inputs!$B$40,Inputs!$A$29:$K$33,6,FALSE())*(Inputs!$B$25/14)*Inputs!$B$5+VLOOKUP(Inputs!$B$40,Inputs!$A$29:$K$33,7,FALSE())*(Inputs!$B$25/14)*Inputs!$B$12+VLOOKUP(Inputs!$B$40,Inputs!$A$29:$K$33,8,FALSE())*(Inputs!$B$25/14)*Inputs!$B$13),C11*((VLOOKUP(Inputs!$B$40,Inputs!$A$29:$K$33,3,FALSE())*(Inputs!$B$25/14)*Inputs!$B$5+VLOOKUP(Inputs!$B$40,Inputs!$A$29:$K$33,4,FALSE())*(Inputs!$B$25/14)*Inputs!$B$12+VLOOKUP(Inputs!$B$40,Inputs!$A$29:$K$33,5,FALSE())*(Inputs!$B$25/14)*Inputs!$B$13)+Inputs!$B$18)+(1-C11)*IF(Inputs!$B$42="soc",(INDEX(Inputs!$A$37:$C$37,1,1)*(Inputs!$B$25/14)*Inputs!$B$5+INDEX(Inputs!$A$37:$C$37,1,2)*(Inputs!$B$25/14)*Inputs!$B$12+INDEX(Inputs!$A$37:$C$37,1,3)*(Inputs!$B$25/14)*Inputs!$B$13),(VLOOKUP(Inputs!$B$40,Inputs!$A$29:$K$33,9,FALSE())*(Inputs!$B$25/14)*Inputs!$B$5+VLOOKUP(Inputs!$B$40,Inputs!$A$29:$K$33,10,FALSE())*(Inputs!$B$25/14)*Inputs!$B$12+VLOOKUP(Inputs!$B$40,Inputs!$A$29:$K$33,11,FALSE())*(Inputs!$B$25/14)*Inputs!$B$13))) -> 182.58922 | E11: =0 -> 0 | F11: =(INDEX(Inputs!$A$37:$C$37,1,1)*(Inputs!$B$25/14)*Inputs!$B$5+INDEX(Inputs!$A$37:$C$37,1,2)*(Inputs!$B$25/14)*Inputs!$B$12+INDEX(Inputs!$A$37:$C$37,1,3)*(Inputs!$B$25/14)*Inputs!$B$13) -> 327.59593
A12: 4 | B12: =A12<=Inputs!$B$17 -> FALSE | C12: =IF(Inputs!$B$41="none",IF(A12=2,C11*(1-Inputs!$B$22),C11),IF(Inputs!$B$41="constant",C11*(1-Inputs!$B$22),C11*(1-Inputs!$B$22*(0.9^(A12-2))))) -> 0.276 | D12: =IF(B12,C12*(VLOOKUP(Inputs!$B$40,Inputs!$A$29:$K$33,3,FALSE())*(Inputs!$B$25/14)*Inputs!$B$5+VLOOKUP(Inputs!$B$40,Inputs!$A$29:$K$33,4,FALSE())*(Inputs!$B$25/14)*Inputs!$B$12+VLOOKUP(Inputs!$B$40,Inputs!$A$29:$K$33,5,FALSE())*(Inputs!$B$25/14)*Inputs!$B$13)+(1-C12)*(VLOOKUP(Inputs!$B$40,Inputs!$A$29:$K$33,6,FALSE())*(Inputs!$B$25/14)*Inputs!$B$5+VLOOKUP(Inputs!$B$40,Inputs!$A$29:$K$33,7,FALSE())*(Inputs!$B$25/14)*Inputs!$B$12+VLOOKUP(Inputs!$B$40,Inputs!$A$29:$K$33,8,FALSE())*(Inputs!$B$25/14)*Inputs!$B$13),C12*((VLOOKUP(Inputs!$B$40,Inputs!$A$29:$K$33,3,FALSE())*(Inputs!$B$25/14)*Inputs!$B$5+VLOOKUP(Inputs!$B$40,Inputs!$A$29:$K$33,4,FALSE())*(Inputs!$B$25/14)*Inputs!$B$12+VLOOKUP(Inputs!$B$40,Inputs!$A$29:$K$33,5,FALSE())*(Inputs!$B$25/14)*Inputs!$B$13)+Inputs!$B$18)+(1-C12)*IF(Inputs!$B$42="soc",(INDEX(Inputs!$A$37:$C$37,1,1)*(Inputs!$B$25/14)*Inputs!$B$5+INDEX(Inputs!$A$37:$C$37,1,2)*(Inputs!$B$25/14)*Inputs!$B$12+INDEX(Inputs!$A$37:$C$37,1,3)*(Inputs!$B$25/14)*Inputs!$B$13),(VLOOKUP(Inputs!$B$40,Inputs!$A$29:$K$33,9,FALSE())*(Inputs!$B$25/14)*Inputs!$B$5+VLOOKUP(Inputs!$B$40,Inputs!$A$29:$K$33,10,FALSE())*(Inputs!$B$25/14)*Inputs!$B$12+VLOOKUP(Inputs!$B$40,Inputs!$A$29:$K$33,11,FALSE())*(Inputs!$B$25/14)*Inputs!$B$13))) -> 324.85928 | E12: =0 -> 0 | F12: =(INDEX(Inputs!$A$37:$C$37,1,1)*(Inputs!$B$25/14)*Inputs!$B$5+INDEX(Inputs!$A$37:$C$37,1,2)*(Inputs!$B$25/14)*Inputs!$B$12+INDEX(Inputs!$A$37:$C$37,1,3)*(Inputs!$B$25/14)*Inputs!$B$13) -> 327.59593
A13: 5 | B13: =A13<=Inputs!$B$17 -> FALSE | C13: =IF(Inputs!$B$41="none",IF(A13=2,C12*(1-Inputs!$B$22),C12),IF(Inputs!$B$41="constant",C12*(1-Inputs!$B$22),C12*(1-Inputs!$B$22*(0.9^(A13-2))))) -> 0.276 | D13: =IF(B13,C13*(VLOOKUP(Inputs!$B$40,Inputs!$A$29:$K$33,3,FALSE())*(Inputs!$B$25/14)*Inputs!$B$5+VLOOKUP(Inputs!$B$40,Inputs!$A$29:$K$33,4,FALSE())*(Inputs!$B$25/14)*Inputs!$B$12+VLOOKUP(Inputs!$B$40,Inputs!$A$29:$K$33,5,FALSE())*(Inputs!$B$25/14)*Inputs!$B$13)+(1-C13)*(VLOOKUP(Inputs!$B$40,Inputs!$A$29:$K$33,6,FALSE())*(Inputs!$B$25/14)*Inputs!$B$5+VLOOKUP(Inputs!$B$40,Inputs!$A$29:$K$33,7,FALSE())*(Inputs!$B$25/14)*Inputs!$B$12+VLOOKUP(Inputs!$B$40,Inputs!$A$29:$K$33,8,FALSE())*(Inputs!$B$25/14)*Inputs!$B$13),C13*((VLOOKUP(Inputs!$B$40,Inputs!$A$29:$K$33,3,FALSE())*(Inputs!$B$25/14)*Inputs!$B$5+VLOOKUP(Inputs!$B$40,Inputs!$A$29:$K$33,4,FALSE())*(Inputs!$B$25/14)*Inputs!$B$12+VLOOKUP(Inputs!$B$40,Inputs!$A$29:$K$33,5,FALSE())*(Inputs!$B$25/14)*Inputs!$B$13)+Inputs!$B$18)+(1-C13)*IF(Inputs!$B$42="soc",(INDEX(Inputs!$A$37:$C$37,1,1)*(Inputs!$B$25/14)*Inputs!$B$5+INDEX(Inputs!$A$37:$C$37,1,2)*(Inputs!$B$25/14)*Inputs!$B$12+INDEX(Inputs!$A$37:$C$37,1,3)*(Inputs!$B$25/14)*Inputs!$B$13),(VLOOKUP(Inputs!$B$40,Inputs!$A$29:$K$33,9,FALSE())*(Inputs!$B$25/14)*Inputs!$B$5+VLOOKUP(Inputs!$B$40,Inputs!$A$29:$K$33,10,FALSE())*(Inputs!$B$25/14)*Inputs!$B$12+VLOOKUP(Inputs!$B$40,Inputs!$A$29:$K$33,11,FALSE())*(Inputs!$B$25/14)*Inputs!$B$13))) -> 324.85928 | E13: =0 -> 0 | F13: =(INDEX(Inputs!$A$37:$C$37,1,1)*(Inputs!$B$25/14)*Inputs!$B$5+INDEX(Inputs!$A$37:$C$37,1,2)*(Inputs!$B$25/14)*Inputs!$B$12+INDEX(Inputs!$A$37:$C$37,1,3)*(Inputs!$B$25/14)*Inputs!$B$13) -> 327.59593
A14: 6 | B14: =A14<=Inputs!$B$17 -> FALSE | C14: =IF(Inputs!$B$41="none",IF(A14=2,C13*(1-Inputs!$B$22),C13),IF(Inputs!$B$41="constant",C13*(1-Inputs!$B$22),C13*(1-Inputs!$B$22*(0.9^(A14-2))))) -> 0.276 | D14: =IF(B14,C14*(VLOOKUP(Inputs!$B$40,Inputs!$A$29:$K$33,3,FALSE())*(Inputs!$B$25/14)*Inputs!$B$5+VLOOKUP(Inputs!$B$40,Inputs!$A$29:$K$33,4,FALSE())*(Inputs!$B$25/14)*Inputs!$B$12+VLOOKUP(Inputs!$B$40,Inputs!$A$29:$K$33,5,FALSE())*(Inputs!$B$25/14)*Inputs!$B$13)+(1-C14)*(VLOOKUP(Inputs!$B$40,Inputs!$A$29:$K$33,6,FALSE())*(Inputs!$B$25/14)*Inputs!$B$5+VLOOKUP(Inputs!$B$40,Inputs!$A$29:$K$33,7,FALSE())*(Inputs!$B$25/14)*Inputs!$B$12+VLOOKUP(Inputs!$B$40,Inputs!$A$29:$K$33,8,FALSE())*(Inputs!$B$25/14)*Inputs!$B$13),C14*((VLOOKUP(Inputs!$B$40,Inputs!$A$29:$K$33,3,FALSE())*(Inputs!$B$25/14)*Inputs!$B$5+VLOOKUP(Inputs!$B$40,Inputs!$A$29:$K$33,4,FALSE())*(Inputs!$B$25/14)*Inputs!$B$12+VLOOKUP(Inputs!$B$40,Inputs!$A$29:$K$33,5,FALSE())*(Inputs!$B$25/14)*Inputs!$B$13)+Inputs!$B$18)+(1-C14)*IF(Inputs!$B$42="soc",(INDEX(Inputs!$A$37:$C$37,1,1)*(Inputs!$B$25/14)*Inputs!$B$5+INDEX(Inputs!$A$37:$C$37,1,2)*(Inputs!$B$25/14)*Inputs!$B$12+INDEX(Inputs!$A$37:$C$37,1,3)*(Inputs!$B$25/14)*Inputs!$B$13),(VLOOKUP(Inputs!$B$40,Inputs!$A$29:$K$33,9,FALSE())*(Inputs!$B$25/14)*Inputs!$B$5+VLOOKUP(Inputs!$B$40,Inputs!$A$29:$K$33,10,FALSE())*(Inputs!$B$25/14)*Inputs!$B$12+VLOOKUP(Inputs!$B$40,Inputs!$A$29:$K$33,11,FALSE())*(Inputs!$B$25/14)*Inputs!$B$13))) -> 324.85928 | E14: =0 -> 0 | F14: =(INDEX(Inputs!$A$37:$C$37,1,1)*(Inputs!$B$25/14)*Inputs!$B$5+INDEX(Inputs!$A$37:$C$37,1,2)*(Inputs!$B$25/14)*Inputs!$B$12+INDEX(Inputs!$A$37:$C$37,1,3)*(Inputs!$B$25/14)*Inputs!$B$13) -> 327.59593
A15: 7 | B15: =A15<=Inputs!$B$17 -> FALSE | C15: =IF(Inputs!$B$41="none",IF(A15=2,C14*(1-Inputs!$B$22),C14),IF(Inputs!$B$41="constant",C14*(1-Inputs!$B$22),C14*(1-Inputs!$B$22*(0.9^(A15-2))))) -> 0.276 | D15: =IF(B15,C15*(VLOOKUP(Inputs!$B$40,Inputs!$A$29:$K$33,3,FALSE())*(Inputs!$B$25/14)*Inputs!$B$5+VLOOKUP(Inputs!$B$40,Inputs!$A$29:$K$33,4,FALSE())*(Inputs!$B$25/14)*Inputs!$B$12+VLOOKUP(Inputs!$B$40,Inputs!$A$29:$K$33,5,FALSE())*(Inputs!$B$25/14)*Inputs!$B$13)+(1-C15)*(VLOOKUP(Inputs!$B$40,Inputs!$A$29:$K$33,6,FALSE())*(Inputs!$B$25/14)*Inputs!$B$5+VLOOKUP(Inputs!$B$40,Inputs!$A$29:$K$33,7,FALSE())*(Inputs!$B$25/14)*Inputs!$B$12+VLOOKUP(Inputs!$B$40,Inputs!$A$29:$K$33,8,FALSE())*(Inputs!$B$25/14)*Inputs!$B$13),C15*((VLOOKUP(Inputs!$B$40,Inputs!$A$29:$K$33,3,FALSE())*(Inputs!$B$25/14)*Inputs!$B$5+VLOOKUP(Inputs!$B$40,Inputs!$A$29:$K$33,4,FALSE())*(Inputs!$B$25/14)*Inputs!$B$12+VLOOKUP(Inputs!$B$40,Inputs!$A$29:$K$33,5,FALSE())*(Inputs!$B$25/14)*Inputs!$B$13)+Inputs!$B$18)+(1-C15)*IF(Inputs!$B$42="soc",(INDEX(Inputs!$A$37:$C$37,1,1)*(Inputs!$B$25/14)*Inputs!$B$5+INDEX(Inputs!$A$37:$C$37,1,2)*(Inputs!$B$25/14)*Inputs!$B$12+INDEX(Inputs!$A$37:$C$37,1,3)*(Inputs!$B$25/14)*Inputs!$B$13),(VLOOKUP(Inputs!$B$40,Inputs!$A$29:$K$33,9,FALSE())*(Inputs!$B$25/14)*Inputs!$B$5+VLOOKUP(Inputs!$B$40,Inputs!$A$29:$K$33,10,FALSE())*(Inputs!$B$25/14)*Inputs!$B$12+VLOOKUP(Inputs!$B$40,Inputs!$A$29:$K$33,11,FALSE())*(Inputs!$B$25/14)*Inputs!$B$13))) -> 324.85928 | E15: =0 -> 0 | F15: =(INDEX(Inputs!$A$37:$C$37,1,1)*(Inputs!$B$25/14)*Inputs!$B$5+INDEX(Inputs!$A$37:$C$37,1,2)*(Inputs!$B$25/14)*Inputs!$B$12+INDEX(Inputs!$A$37:$C$37,1,3)*(Inputs!$B$25/14)*Inputs!$B$13) -> 327.59593
A16: 8 | B16: =A16<=Inputs!$B$17 -> FALSE | C16: =IF(Inputs!$B$41="none",IF(A16=2,C15*(1-Inputs!$B$22),C15),IF(Inputs!$B$41="constant",C15*(1-Inputs!$B$22),C15*(1-Inputs!$B$22*(0.9^(A16-2))))) -> 0.276 | D16: =IF(B16,C16*(VLOOKUP(Inputs!$B$40,Inputs!$A$29:$K$33,3,FALSE())*(Inputs!$B$25/14)*Inputs!$B$5+VLOOKUP(Inputs!$B$40,Inputs!$A$29:$K$33,4,FALSE())*(Inputs!$B$25/14)*Inputs!$B$12+VLOOKUP(Inputs!$B$40,Inputs!$A$29:$K$33,5,FALSE())*(Inputs!$B$25/14)*Inputs!$B$13)+(1-C16)*(VLOOKUP(Inputs!$B$40,Inputs!$A$29:$K$33,6,FALSE())*(Inputs!$B$25/14)*Inputs!$B$5+VLOOKUP(Inputs!$B$40,Inputs!$A$29:$K$33,7,FALSE())*(Inputs!$B$25/14)*Inputs!$B$12+VLOOKUP(Inputs!$B$40,Inputs!$A$29:$K$33,8,FALSE())*(Inputs!$B$25/14)*Inputs!$B$13),C16*((VLOOKUP(Inputs!$B$40,Inputs!$A$29:$K$33,3,FALSE())*(Inputs!$B$25/14)*Inputs!$B$5+VLOOKUP(Inputs!$B$40,Inputs!$A$29:$K$33,4,FALSE())*(Inputs!$B$25/14)*Inputs!$B$12+VLOOKUP(Inputs!$B$40,Inputs!$A$29:$K$33,5,FALSE())*(Inputs!$B$25/14)*Inputs!$B$13)+Inputs!$B$18)+(1-C16)*IF(Inputs!$B$42="soc",(INDEX(Inputs!$A$37:$C$37,1,1)*(Inputs!$B$25/14)*Inputs!$B$5+INDEX(Inputs!$A$37:$C$37,1,2)*(Inputs!$B$25/14)*Inputs!$B$12+INDEX(Inputs!$A$37:$C$37,1,3)*(Inputs!$B$25/14)*Inputs!$B$13),(VLOOKUP(Inputs!$B$40,Inputs!$A$29:$K$33,9,FALSE())*(Inputs!$B$25/14)*Inputs!$B$5+VLOOKUP(Inputs!$B$40,Inputs!$A$29:$K$33,10,FALSE())*(Inputs!$B$25/14)*Inputs!$B$12+VLOOKUP(Inputs!$B$40,Inputs!$A$29:$K$33,11,FALSE())*(Inputs!$B$25/14)*Inputs!$B$13))) -> 324.85928 | E16: =0 -> 0 | F16: =(INDEX(Inputs!$A$37:$C$37,1,1)*(Inputs!$B$25/14)*Inputs!$B$5+INDEX(Inputs!$A$37:$C$37,1,2)*(Inputs!$B$25/14)*Inputs!$B$12+INDEX(Inputs!$A$37:$C$37,1,3)*(Inputs!$B$25/14)*Inputs!$B$13) -> 327.59593
A17: 9 | B17: =A17<=Inputs!$B$17 -> FALSE | C17: =IF(Inputs!$B$41="none",IF(A17=2,C16*(1-Inputs!$B$22),C16),IF(Inputs!$B$41="constant",C16*(1-Inputs!$B$22),C16*(1-Inputs!$B$22*(0.9^(A17-2))))) -> 0.276 | D17: =IF(B17,C17*(VLOOKUP(Inputs!$B$40,Inputs!$A$29:$K$33,3,FALSE())*(Inputs!$B$25/14)*Inputs!$B$5+VLOOKUP(Inputs!$B$40,Inputs!$A$29:$K$33,4,FALSE())*(Inputs!$B$25/14)*Inputs!$B$12+VLOOKUP(Inputs!$B$40,Inputs!$A$29:$K$33,5,FALSE())*(Inputs!$B$25/14)*Inputs!$B$13)+(1-C17)*(VLOOKUP(Inputs!$B$40,Inputs!$A$29:$K$33,6,FALSE())*(Inputs!$B$25/14)*Inputs!$B$5+VLOOKUP(Inputs!$B$40,Inputs!$A$29:$K$33,7,FALSE())*(Inputs!$B$25/14)*Inputs!$B$12+VLOOKUP(Inputs!$B$40,Inputs!$A$29:$K$33,8,FALSE())*(Inputs!$B$25/14)*Inputs!$B$13),C17*((VLOOKUP(Inputs!$B$40,Inputs!$A$29:$K$33,3,FALSE())*(Inputs!$B$25/14)*Inputs!$B$5+VLOOKUP(Inputs!$B$40,Inputs!$A$29:$K$33,4,FALSE())*(Inputs!$B$25/14)*Inputs!$B$12+VLOOKUP(Inputs!$B$40,Inputs!$A$29:$K$33,5,FALSE())*(Inputs!$B$25/14)*Inputs!$B$13)+Inputs!$B$18)+(1-C17)*IF(Inputs!$B$42="soc",(INDEX(Inputs!$A$37:$C$37,1,1)*(Inputs!$B$25/14)*Inputs!$B$5+INDEX(Inputs!$A$37:$C$37,1,2)*(Inputs!$B$25/14)*Inputs!$B$12+INDEX(Inputs!$A$37:$C$37,1,3)*(Inputs!$B$25/14)*Inputs!$B$13),(VLOOKUP(Inputs!$B$40,Inputs!$A$29:$K$33,9,FALSE())*(Inputs!$B$25/14)*Inputs!$B$5+VLOOKUP(Inputs!$B$40,Inputs!$A$29:$K$33,10,FALSE())*(Inputs!$B$25/14)*Inputs!$B$12+VLOOKUP(Inputs!$B$40,Inputs!$A$29:$K$33,11,FALSE())*(Inputs!$B$25/14)*Inputs!$B$13))) -> 324.85928 | E17: =0 -> 0 | F17: =(INDEX(Inputs!$A$37:$C$37,1,1)*(Inputs!$B$25/14)*Inputs!$B$5+INDEX(Inputs!$A$37:$C$37,1,2)*(Inputs!$B$25/14)*Inputs!$B$12+INDEX(Inputs!$A$37:$C$37,1,3)*(Inputs!$B$25/14)*Inputs!$B$13) -> 327.59593
A18: 10 | B18: =A18<=Inputs!$B$17 -> FALSE | C18: =IF(Inputs!$B$41="none",IF(A18=2,C17*(1-Inputs!$B$22),C17),IF(Inputs!$B$41="constant",C17*(1-Inputs!$B$22),C17*(1-Inputs!$B$22*(0.9^(A18-2))))) -> 0.276 | D18: =IF(B18,C18*(VLOOKUP(Inputs!$B$40,Inputs!$A$29:$K$33,3,FALSE())*(Inputs!$B$25/14)*Inputs!$B$5+VLOOKUP(Inputs!$B$40,Inputs!$A$29:$K$33,4,FALSE())*(Inputs!$B$25/14)*Inputs!$B$12+VLOOKUP(Inputs!$B$40,Inputs!$A$29:$K$33,5,FALSE())*(Inputs!$B$25/14)*Inputs!$B$13)+(1-C18)*(VLOOKUP(Inputs!$B$40,Inputs!$A$29:$K$33,6,FALSE())*(Inputs!$B$25/14)*Inputs!$B$5+VLOOKUP(Inputs!$B$40,Inputs!$A$29:$K$33,7,FALSE())*(Inputs!$B$25/14)*Inputs!$B$12+VLOOKUP(Inputs!$B$40,Inputs!$A$29:$K$33,8,FALSE())*(Inputs!$B$25/14)*Inputs!$B$13),C18*((VLOOKUP(Inputs!$B$40,Inputs!$A$29:$K$33,3,FALSE())*(Inputs!$B$25/14)*Inputs!$B$5+VLOOKUP(Inputs!$B$40,Inputs!$A$29:$K$33,4,FALSE())*(Inputs!$B$25/14)*Inputs!$B$12+VLOOKUP(Inputs!$B$40,Inputs!$A$29:$K$33,5,FALSE())*(Inputs!$B$25/14)*Inputs!$B$13)+Inputs!$B$18)+(1-C18)*IF(Inputs!$B$42="soc",(INDEX(Inputs!$A$37:$C$37,1,1)*(Inputs!$B$25/14)*Inputs!$B$5+INDEX(Inputs!$A$37:$C$37,1,2)*(Inputs!$B$25/14)*Inputs!$B$12+INDEX(Inputs!$A$37:$C$37,1,3)*(Inputs!$B$25/14)*Inputs!$B$13),(VLOOKUP(Inputs!$B$40,Inputs!$A$29:$K$33,9,FALSE())*(Inputs!$B$25/14)*Inputs!$B$5+VLOOKUP(Inputs!$B$40,Inputs!$A$29:$K$33,10,FALSE())*(Inputs!$B$25/14)*Inputs!$B$12+VLOOKUP(Inputs!$B$40,Inputs!$A$29:$K$33,11,FALSE())*(Inputs!$B$25/14)*Inputs!$B$13))) -> 324.85928 | E18: =0 -> 0 | F18: =(INDEX(Inputs!$A$37:$C$37,1,1)*(Inputs!$B$25/14)*Inputs!$B$5+INDEX(Inputs!$A$37:$C$37,1,2)*(Inputs!$B$25/14)*Inputs!$B$12+INDEX(Inputs!$A$37:$C$37,1,3)*(Inputs!$B$25/14)*Inputs!$B$13) -> 327.59593
A19: 11 | B19: =A19<=Inputs!$B$17 -> FALSE | C19: =IF(Inputs!$B$41="none",IF(A19=2,C18*(1-Inputs!$B$22),C18),IF(Inputs!$B$41="constant",C18*(1-Inputs!$B$22),C18*(1-Inputs!$B$22*(0.9^(A19-2))))) -> 0.276 | D19: =IF(B19,C19*(VLOOKUP(Inputs!$B$40,Inputs!$A$29:$K$33,3,FALSE())*(Inputs!$B$25/14)*Inputs!$B$5+VLOOKUP(Inputs!$B$40,Inputs!$A$29:$K$33,4,FALSE())*(Inputs!$B$25/14)*Inputs!$B$12+VLOOKUP(Inputs!$B$40,Inputs!$A$29:$K$33,5,FALSE())*(Inputs!$B$25/14)*Inputs!$B$13)+(1-C19)*(VLOOKUP(Inputs!$B$40,Inputs!$A$29:$K$33,6,FALSE())*(Inputs!$B$25/14)*Inputs!$B$5+VLOOKUP(Inputs!$B$40,Inputs!$A$29:$K$33,7,FALSE())*(Inputs!$B$25/14)*Inputs!$B$12+VLOOKUP(Inputs!$B$40,Inputs!$A$29:$K$33,8,FALSE())*(Inputs!$B$25/14)*Inputs!$B$13),C19*((VLOOKUP(Inputs!$B$40,Inputs!$A$29:$K$33,3,FALSE())*(Inputs!$B$25/14)*Inputs!$B$5+VLOOKUP(Inputs!$B$40,Inputs!$A$29:$K$33,4,FALSE())*(Inputs!$B$25/14)*Inputs!$B$12+VLOOKUP(Inputs!$B$40,Inputs!$A$29:$K$33,5,FALSE())*(Inputs!$B$25/14)*Inputs!$B$13)+Inputs!$B$18)+(1-C19)*IF(Inputs!$B$42="soc",(INDEX(Inputs!$A$37:$C$37,1,1)*(Inputs!$B$25/14)*Inputs!$B$5+INDEX(Inputs!$A$37:$C$37,1,2)*(Inputs!$B$25/14)*Inputs!$B$12+INDEX(Inputs!$A$37:$C$37,1,3)*(Inputs!$B$25/14)*Inputs!$B$13),(VLOOKUP(Inputs!$B$40,Inputs!$A$29:$K$33,9,FALSE())*(Inputs!$B$25/14)*Inputs!$B$5+VLOOKUP(Inputs!$B$40,Inputs!$A$29:$K$33,10,FALSE())*(Inputs!$B$25/14)*Inputs!$B$12+VLOOKUP(Inputs!$B$40,Inputs!$A$29:$K$33,11,FALSE())*(Inputs!$B$25/14)*Inputs!$B$13))) -> 324.85928 | E19: =0 -> 0 | F19: =(INDEX(Inputs!$A$37:$C$37,1,1)*(Inputs!$B$25/14)*Inputs!$B$5+INDEX(Inputs!$A$37:$C$37,1,2)*(Inputs!$B$25/14)*Inputs!$B$12+INDEX(Inputs!$A$37:$C$37,1,3)*(Inputs!$B$25/14)*Inputs!$B$13) -> 327.59593
A20: 12 | B20: =A20<=Inputs!$B$17 -> FALSE | C20: =IF(Inputs!$B$41="none",IF(A20=2,C19*(1-Inputs!$B$22),C19),IF(Inputs!$B$41="constant",C19*(1-Inputs!$B$22),C19*(1-Inputs!$B$22*(0.9^(A20-2))))) -> 0.276 | D20: =IF(B20,C20*(VLOOKUP(Inputs!$B$40,Inputs!$A$29:$K$33,3,FALSE())*(Inputs!$B$25/14)*Inputs!$B$5+VLOOKUP(Inputs!$B$40,Inputs!$A$29:$K$33,4,FALSE())*(Inputs!$B$25/14)*Inputs!$B$12+VLOOKUP(Inputs!$B$40,Inputs!$A$29:$K$33,5,FALSE())*(Inputs!$B$25/14)*Inputs!$B$13)+(1-C20)*(VLOOKUP(Inputs!$B$40,Inputs!$A$29:$K$33,6,FALSE())*(Inputs!$B$25/14)*Inputs!$B$5+VLOOKUP(Inputs!$B$40,Inputs!$A$29:$K$33,7,FALSE())*(Inputs!$B$25/14)*Inputs!$B$12+VLOOKUP(Inputs!$B$40,Inputs!$A$29:$K$33,8,FALSE())*(Inputs!$B$25/14)*Inputs!$B$13),C20*((VLOOKUP(Inputs!$B$40,Inputs!$A$29:$K$33,3,FALSE())*(Inputs!$B$25/14)*Inputs!$B$5+VLOOKUP(Inputs!$B$40,Inputs!$A$29:$K$33,4,FALSE())*(Inputs!$B$25/14)*Inputs!$B$12+VLOOKUP(Inputs!$B$40,Inputs!$A$29:$K$33,5,FALSE())*(Inputs!$B$25/14)*Inputs!$B$13)+Inputs!$B$18)+(1-C20)*IF(Inputs!$B$42="soc",(INDEX(Inputs!$A$37:$C$37,1,1)*(Inputs!$B$25/14)*Inputs!$B$5+INDEX(Inputs!$A$37:$C$37,1,2)*(Inputs!$B$25/14)*Inputs!$B$12+INDEX(Inputs!$A$37:$C$37,1,3)*(Inputs!$B$25/14)*Inputs!$B$13),(VLOOKUP(Inputs!$B$40,Inputs!$A$29:$K$33,9,FALSE())*(Inputs!$B$25/14)*Inputs!$B$5+VLOOKUP(Inputs!$B$40,Inputs!$A$29:$K$33,10,FALSE())*(Inputs!$B$25/14)*Inputs!$B$12+VLOOKUP(Inputs!$B$40,Inputs!$A$29:$K$33,11,FALSE())*(Inputs!$B$25/14)*Inputs!$B$13))) -> 324.85928 | E20: =0 -> 0 | F20: =(INDEX(Inputs!$A$37:$C$37,1,1)*(Inputs!$B$25/14)*Inputs!$B$5+INDEX(Inputs!$A$37:$C$37,1,2)*(Inputs!$B$25/14)*Inputs!$B$12+INDEX(Inputs!$A$37:$C$37,1,3)*(Inputs!$B$25/14)*Inputs!$B$13) -> 327.59593
A22: TOTAL (12 months) | D22: =SUM(D9:D20) -> 3458.957 | F22: =SUM(F9:F20) -> 3913.0365
A23: Difference (gCore + SoC minus SoC) | D23: =D22-F22 -> -454.07954

Sheet Results
A1: gammaCore for Chronic Cluster Headache — RESULTS
A2: Live results for the scenario currently selected on the Inputs sheet, validated against the company-reported base case (Table C16–C18).
A4: HEADLINE RESULTS (Table C16)
B5: gammaCore + SoC (£) | C5: SoC alone (£) | D5: Difference (£) | E5: Notes
A6: Model result (current scenario) | B6: =Model!D22 -> 3458.957 | C6: =Model!F22 -> 3913.0365 | D6: =B6-C6 -> -454.07954
A7: Company-reported base case | B7: 3448.45 | C7: 3898.86 | D7: -450.42 | E7: Source: Sponsor submission, Table C16 (base case: 50% definition, no response loss, SoC non-responder use)
A8: Difference vs. company-reported (this replication) | D8: =B6-B7 -> 10.506997 | E8: Only exact when Inputs selectors = 50 / none / soc / No (base case). Small residual gap (~1%) is due to 2–3 sig-fig rounding of doses in the published Table C10.
A10: COST BY CATEGORY, CURRENT SCENARIO (cf. Table C17)
A11: Item | B11: gammaCore + SoC (£) | C11: SoC (£) | D11: Increment (£) | E11: Company-reported (base case only)
A12: gammaCore device | B12: =IF(Model!B9,0,Model!C9*Inputs!$B$18)+IF(Model!B10,0,Model!C10*Inputs!$B$18)+IF(Model!B11,0,Model!C11*Inputs!$B$18)+IF(Model!B12,0,Model!C12*Inputs!$B$18)+IF(Model!B13,0,Model!C13*Inputs!$B$18)+IF(Model!B14,0,Model!C14*Inputs!$B$18)+IF(Model!B15,0,Model!C15*Inputs!$B$18)+IF(Model!B16,0,Model!C16*Inputs!$B$18)+IF(Model!B17,0,Model!C17*Inputs!$B$18)+IF(Model!B18,0,Model!C18*Inputs!$B$18)+IF(Model!B19,0,Model!C19*Inputs!$B$18)+IF(Model!B20,0,Model!C20*Inputs!$B$18) -> 517.5 | C12: 0 | D12: =B12-C12 -> 517.5 | E12: GC device only
A13: Zolmitriptan | B13: =IF(Model!B9,Model!C9*(VLOOKUP(Inputs!$B$40,Inputs!$A$29:$K$33,3,FALSE())*(Inputs!$B$25/14)*Inputs!$B$5)+(1-Model!C9)*(VLOOKUP(Inputs!$B$40,Inputs!$A$29:$K$33,6,FALSE())*(Inputs!$B$25/14)*Inputs!$B$5),Model!C9*(VLOOKUP(Inputs!$B$40,Inputs!$A$29:$K$33,3,FALSE())*(Inputs!$B$25/14)*Inputs!$B$5)+(1-Model!C9)*(IF(Inputs!$B$42="soc",INDEX(Inputs!$A$37:$C$37,1,1)*(Inputs!$B$25/14)*Inputs!$B$5,VLOOKUP(Inputs!$B$40,Inputs!$A$29:$K$33,9,FALSE())*(Inputs!$B$25/14)*Inputs!$B$5)))+IF(Model!B10,Model!C10*(VLOOKUP(Inputs!$B$40,Inputs!$A$29:$K$33,3,FALSE())*(Inputs!$B$25/14)*Inputs!$B$5)+(1-Model!C10)*(VLOOKUP(Inputs!$B$40,Inputs!$A$29:$K$33,6,FALSE())*(Inputs!$B$25/14)*Inputs!$B$5),Model!C10*(VLOOKUP(Inputs!$B$40,Inputs!$A$29:$K$33,3,FALSE())*(Inputs!$B$25/14)*Inputs!$B$5)+(1-Model!C10)*(IF(Inputs!$B$42="soc",INDEX(Inputs!$A$37:$C$37,1,1)*(Inputs!$B$25/14)*Inputs!$B$5,VLOOKUP(Inputs!$B$40,Inputs!$A$29:$K$33,9,FALSE())*(Inputs!$B$25/14)*Inputs!$B$5)))+IF(Model!B11,Model!C11*(VLOOKUP(Inputs!$B$40,Inputs!$A$29:$K$33,3,FALSE())*(Inputs!$B$25/14)*Inputs!$B$5)+(1-Model!C11)*(VLOOKUP(Inputs!$B$40,Inputs!$A$29:$K$33,6,FALSE())*(Inputs!$B$25/14)*Inputs!$B$5),Model!C11*(VLOOKUP(Inputs!$B$40,Inputs!$A$29:$K$33,3,FALSE())*(Inputs!$B$25/14)*Inputs!$B$5)+(1-Model!C11)*(IF(Inputs!$B$42="soc",INDEX(Inputs!$A$37:$C$37,1,1)*(Inputs!$B$25/14)*Inputs!$B$5,VLOOKUP(Inputs!$B$40,Inputs!$A$29:$K$33,9,FALSE())*(Inputs!$B$25/14)*Inputs!$B$5)))+IF(Model!B12,Model!C12*(VLOOKUP(Inputs!$B$40,Inputs!$A$29:$K$33,3,FALSE())*(Inputs!$B$25/14)*Inputs!$B$5)+(1-Model!C12)*(VLOOKUP(Inputs!$B$40,Inputs!$A$29:$K$33,6,FALSE())*(Inputs!$B$25/14)*Inputs!$B$5),Model!C12*(VLOOKUP(Inputs!$B$40,Inputs!$A$29:$K$33,3,FALSE())*(Inputs!$B$25/14)*Inputs!$B$5)+(1-Model!C12)*(IF(Inputs!$B$42="soc",INDEX(Inputs!$A$37:$C$37,1,1)*(Inputs!$B$25/14)*Inputs!$B$5,VLOOKUP(Inputs!$B$40,Inputs!$A$29:$K$33,9,FALSE())*(Inputs!$B$25/14)*Inputs!$B$5)))+IF(Model!B13,Model!C13*(VLOOKUP(Inputs!$B$40,Inputs!$A$29:$K$33,3,FALSE())*(Inputs!$B$25/14)*Inputs!$B$5)+(1-Model!C13)*(VLOOKUP(Inputs!$B$40,Inputs!$A$29:$K$33,6,FALSE())*(Inputs!$B$25/14)*Inputs!$B$5),Model!C13*(VLOOKUP(Inputs!$B$40,Inputs!$A$29:$K$33,3,FALSE())*(Inputs!$B$25/14)*Inputs!$B$5)+(1-Model!C13)*(IF(Inputs!$B$42="soc",INDEX(Inputs!$A$37:$C$37,1,1)*(Inputs!$B$25/14)*Inputs!$B$5,VLOOKUP(Inputs!$B$40,Inputs!$A$29:$K$33,9,FALSE())*(Inputs!$B$25/14)*Inputs!$B$5)))+IF(Model!B14,Model!C14*(VLOOKUP(Inputs!$B$40,Inputs!$A$29:$K$33,3,FALSE())*(Inputs!$B$25/14)*Inputs!$B$5)+(1-Model!C14)*(VLOOKUP(Inputs!$B$40,Inputs!$A$29:$K$33,6,FALSE())*(Inputs!$B$25/14)*Inputs!$B$5),Model!C14*(VLOOKUP(Inputs!$B$40,Inputs!$A$29:$K$33,3,FALSE())*(Inputs!$B$25/14)*Inputs!$B$5)+(1-Model!C14)*(IF(Inputs!$B$42="soc",INDEX(Inputs!$A$37:$C$37,1,1)*(Inputs!$B$25/14)*Inputs!$B$5,VLOOKUP(Inputs!$B$40,Inputs!$A$29:$K$33,9,FALSE())*(Inputs!$B$25/14)*Inputs!$B$5)))+IF(Model!B15,Model!C15*(VLOOKUP(Inputs!$B$40,Inputs!$A$29:$K$33,3,FALSE())*(Inputs!$B$25/14)*Inputs!$B$5)+(1-Model!C15)*(VLOOKUP(Inputs!$B$40,Inputs!$A$29:$K$33,6,FALSE())*(Inputs!$B$25/14)*Inputs!$B$5),Model!C15*(VLOOKUP(Inputs!$B$40,Inputs!$A$29:$K$33,3,FALSE())*(Inputs!$B$25/14)*Inputs!$B$5)+(1-Model!C15)*(IF(Inputs!$B$42="soc",INDEX(Inputs!$A$37:$C$37,1,1)*(Inputs!$B$25/14)*Inputs!$B$5,VLOOKUP(Inputs!$B$40,Inputs!$A$29:$K$33,9,FALSE())*(Inputs!$B$25/14)*Inputs!$B$5)))+IF(Model!B16,Model!C16*(VLOOKUP(Inputs!$B$40,Inputs!$A$29:$K$33,3,FALSE())*(Inputs!$B$25/14)*Inputs!$B$5)+(1-Model!C16)*(VLOOKUP(Inputs!$B$40,Inputs!$A$29:$K$33,6,FALSE())*(Inputs!$B$25/14)*Inputs!$B$5),Model!C16*(VLOOKUP(Inputs!$B$40,Inputs!$A$29:$K$33,3,FALSE())*(Inputs!$B$25/14)*Inputs!$B$5)+(1-Model!C16)*(IF(Inputs!$B$42="soc",INDEX(Inputs!$A$37:$C$37,1,1)*(Inputs!$B$25/14)*Inputs!$B$5,VLOOKUP(Inputs!$B$40,Inputs!$A$29:$K$33,9,FALSE())*(Inputs!$B$25/14)*Inputs!$B$5)))+IF(Model!B17,Model!C17*(VLOOKUP(Inputs!$B$40,Inputs!$A$29:$K$33,3,FALSE())*(Inputs!$B$25/14)*Inputs!$B$5)+(1-Model!C17)*(VLOOKUP(Inputs!$B$40,Inputs!$A$29:$K$33,6,FALSE())*(Inputs!$B$25/14)*Inputs!$B$5),Model!C17*(VLOOKUP(Inputs!$B$40,Inputs!$A$29:$K$33,3,FALSE())*(Inputs!$B$25/14)*Inputs!$B$5)+(1-Model!C17)*(IF(Inputs!$B$42="soc",INDEX(Inputs!$A$37:$C$37,1,1)*(Inputs!$B$25/14)*Inputs!$B$5,VLOOKUP(Inputs!$B$40,Inputs!$A$29:$K$33,9,FALSE())*(Inputs!$B$25/14)*Inputs!$B$5)))+IF(Model!B18,Model!C18*(VLOOKUP(Inputs!$B$40,Inputs!$A$29:$K$33,3,FALSE())*(Inputs!$B$25/14)*Inputs!$B$5)+(1-Model!C18)*(VLOOKUP(Inputs!$B$40,Inputs!$A$29:$K$33,6,FALSE())*(Inputs!$B$25/14)*Inputs!$B$5),Model!C18*(VLOOKUP(Inputs!$B$40,Inputs!$A$29:$K$33,3,FALSE())*(Inputs!$B$25/14)*Inputs!$B$5)+(1-Model!C18)*(IF(Inputs!$B$42="soc",INDEX(Inputs!$A$37:$C$37,1,1)*(Inputs!$B$25/14)*Inputs!$B$5,VLOOKUP(Inputs!$B$40,Inputs!$A$29:$K$33,9,FALSE())*(Inputs!$B$25/14)*Inputs!$B$5)))+IF(Model!B19,Model!C19*(VLOOKUP(Inputs!$B$40,Inputs!$A$29:$K$33,3,FALSE())*(Inputs!$B$25/14)*Inputs!$B$5)+(1-Model!C19)*(VLOOKUP(Inputs!$B$40,Inputs!$A$29:$K$33,6,FALSE())*(Inputs!$B$25/14)*Inputs!$B$5),Model!C19*(VLOOKUP(Inputs!$B$40,Inputs!$A$29:$K$33,3,FALSE())*(Inputs!$B$25/14)*Inputs!$B$5)+(1-Model!C19)*(IF(Inputs!$B$42="soc",INDEX(Inputs!$A$37:$C$37,1,1)*(Inputs!$B$25/14)*Inputs!$B$5,VLOOKUP(Inputs!$B$40,Inputs!$A$29:$K$33,9,FALSE())*(Inputs!$B$25/14)*Inputs!$B$5)))+IF(Model!B20,Model!C20*(VLOOKUP(Inputs!$B$40,Inputs!$A$29:$K$33,3,FALSE())*(Inputs!$B$25/14)*Inputs!$B$5)+(1-Model!C20)*(VLOOKUP(Inputs!$B$40,Inputs!$A$29:$K$33,6,FALSE())*(Inputs!$B$25/14)*Inputs!$B$5),Model!C20*(VLOOKUP(Inputs!$B$40,Inputs!$A$29:$K$33,3,FALSE())*(Inputs!$B$25/14)*Inputs!$B$5)+(1-Model!C20)*(IF(Inputs!$B$42="soc",INDEX(Inputs!$A$37:$C$37,1,1)*(Inputs!$B$25/14)*Inputs!$B$5,VLOOKUP(Inputs!$B$40,Inputs!$A$29:$K$33,9,FALSE())*(Inputs!$B$25/14)*Inputs!$B$5))) -> 206.90237 | C13: =Model!E9*(VLOOKUP(Inputs!$B$40,Inputs!$A$29:$K$33,3,FALSE())*(Inputs!$B$25/14)*Inputs!$B$5)+(1-Model!E9)*(INDEX(Inputs!$A$37:$C$37,1,1)*(Inputs!$B$25/14)*Inputs!$B$5)+INDEX(Inputs!$A$37:$C$37,1,1)*(Inputs!$B$25/14)*Inputs!$B$5+INDEX(Inputs!$A$37:$C$37,1,1)*(Inputs!$B$25/14)*Inputs!$B$5+INDEX(Inputs!$A$37:$C$37,1,1)*(Inputs!$B$25/14)*Inputs!$B$5+INDEX(Inputs!$A$37:$C$37,1,1)*(Inputs!$B$25/14)*Inputs!$B$5+INDEX(Inputs!$A$37:$C$37,1,1)*(Inputs!$B$25/14)*Inputs!$B$5+INDEX(Inputs!$A$37:$C$37,1,1)*(Inputs!$B$25/14)*Inputs!$B$5+INDEX(Inputs!$A$37:$C$37,1,1)*(Inputs!$B$25/14)*Inputs!$B$5+INDEX(Inputs!$A$37:$C$37,1,1)*(Inputs!$B$25/14)*Inputs!$B$5+INDEX(Inputs!$A$37:$C$37,1,1)*(Inputs!$B$25/14)*Inputs!$B$5+INDEX(Inputs!$A$37:$C$37,1,1)*(Inputs!$B$25/14)*Inputs!$B$5+INDEX(Inputs!$A$37:$C$37,1,1)*(Inputs!$B$25/14)*Inputs!$B$5 -> 205.44172 | D13: =B13-C13 -> 1.4606521 | E13: 206.33 / 204.85 (+1.48)
A14: Sumatriptan | B14: =IF(Model!B9,Model!C9*(VLOOKUP(Inputs!$B$40,Inputs!$A$29:$K$33,4,FALSE())*(Inputs!$B$25/14)*Inputs!$B$12)+(1-Model!C9)*(VLOOKUP(Inputs!$B$40,Inputs!$A$29:$K$33,7,FALSE())*(Inputs!$B$25/14)*Inputs!$B$12),Model!C9*(VLOOKUP(Inputs!$B$40,Inputs!$A$29:$K$33,4,FALSE())*(Inputs!$B$25/14)*Inputs!$B$12)+(1-Model!C9)*(IF(Inputs!$B$42="soc",INDEX(Inputs!$A$37:$C$37,1,2)*(Inputs!$B$25/14)*Inputs!$B$12,VLOOKUP(Inputs!$B$40,Inputs!$A$29:$K$33,10,FALSE())*(Inputs!$B$25/14)*Inputs!$B$12)))+IF(Model!B10,Model!C10*(VLOOKUP(Inputs!$B$40,Inputs!$A$29:$K$33,4,FALSE())*(Inputs!$B$25/14)*Inputs!$B$12)+(1-Model!C10)*(VLOOKUP(Inputs!$B$40,Inputs!$A$29:$K$33,7,FALSE())*(Inputs!$B$25/14)*Inputs!$B$12),Model!C10*(VLOOKUP(Inputs!$B$40,Inputs!$A$29:$K$33,4,FALSE())*(Inputs!$B$25/14)*Inputs!$B$12)+(1-Model!C10)*(IF(Inputs!$B$42="soc",INDEX(Inputs!$A$37:$C$37,1,2)*(Inputs!$B$25/14)*Inputs!$B$12,VLOOKUP(Inputs!$B$40,Inputs!$A$29:$K$33,10,FALSE())*(Inputs!$B$25/14)*Inputs!$B$12)))+IF(Model!B11,Model!C11*(VLOOKUP(Inputs!$B$40,Inputs!$A$29:$K$33,4,FALSE())*(Inputs!$B$25/14)*Inputs!$B$12)+(1-Model!C11)*(VLOOKUP(Inputs!$B$40,Inputs!$A$29:$K$33,7,FALSE())*(Inputs!$B$25/14)*Inputs!$B$12),Model!C11*(VLOOKUP(Inputs!$B$40,Inputs!$A$29:$K$33,4,FALSE())*(Inputs!$B$25/14)*Inputs!$B$12)+(1-Model!C11)*(IF(Inputs!$B$42="soc",INDEX(Inputs!$A$37:$C$37,1,2)*(Inputs!$B$25/14)*Inputs!$B$12,VLOOKUP(Inputs!$B$40,Inputs!$A$29:$K$33,10,FALSE())*(Inputs!$B$25/14)*Inputs!$B$12)))+IF(Model!B12,Model!C12*(VLOOKUP(Inputs!$B$40,Inputs!$A$29:$K$33,4,FALSE())*(Inputs!$B$25/14)*Inputs!$B$12)+(1-Model!C12)*(VLOOKUP(Inputs!$B$40,Inputs!$A$29:$K$33,7,FALSE())*(Inputs!$B$25/14)*Inputs!$B$12),Model!C12*(VLOOKUP(Inputs!$B$40,Inputs!$A$29:$K$33,4,FALSE())*(Inputs!$B$25/14)*Inputs!$B$12)+(1-Model!C12)*(IF(Inputs!$B$42="soc",INDEX(Inputs!$A$37:$C$37,1,2)*(Inputs!$B$25/14)*Inputs!$B$12,VLOOKUP(Inputs!$B$40,Inputs!$A$29:$K$33,10,FALSE())*(Inputs!$B$25/14)*Inputs!$B$12)))+IF(Model!B13,Model!C13*(VLOOKUP(Inputs!$B$40,Inputs!$A$29:$K$33,4,FALSE())*(Inputs!$B$25/14)*Inputs!$B$12)+(1-Model!C13)*(VLOOKUP(Inputs!$B$40,Inputs!$A$29:$K$33,7,FALSE())*(Inputs!$B$25/14)*Inputs!$B$12),Model!C13*(VLOOKUP(Inputs!$B$40,Inputs!$A$29:$K$33,4,FALSE())*(Inputs!$B$25/14)*Inputs!$B$12)+(1-Model!C13)*(IF(Inputs!$B$42="soc",INDEX(Inputs!$A$37:$C$37,1,2)*(Inputs!$B$25/14)*Inputs!$B$12,VLOOKUP(Inputs!$B$40,Inputs!$A$29:$K$33,10,FALSE())*(Inputs!$B$25/14)*Inputs!$B$12)))+IF(Model!B14,Model!C14*(VLOOKUP(Inputs!$B$40,Inputs!$A$29:$K$33,4,FALSE())*(Inputs!$B$25/14)*Inputs!$B$12)+(1-Model!C14)*(VLOOKUP(Inputs!$B$40,Inputs!$A$29:$K$33,7,FALSE())*(Inputs!$B$25/14)*Inputs!$B$12),Model!C14*(VLOOKUP(Inputs!$B$40,Inputs!$A$29:$K$33,4,FALSE())*(Inputs!$B$25/14)*Inputs!$B$12)+(1-Model!C14)*(IF(Inputs!$B$42="soc",INDEX(Inputs!$A$37:$C$37,1,2)*(Inputs!$B$25/14)*Inputs!$B$12,VLOOKUP(Inputs!$B$40,Inputs!$A$29:$K$33,10,FALSE())*(Inputs!$B$25/14)*Inputs!$B$12)))+IF(Model!B15,Model!C15*(VLOOKUP(Inputs!$B$40,Inputs!$A$29:$K$33,4,FALSE())*(Inputs!$B$25/14)*Inputs!$B$12)+(1-Model!C15)*(VLOOKUP(Inputs!$B$40,Inputs!$A$29:$K$33,7,FALSE())*(Inputs!$B$25/14)*Inputs!$B$12),Model!C15*(VLOOKUP(Inputs!$B$40,Inputs!$A$29:$K$33,4,FALSE())*(Inputs!$B$25/14)*Inputs!$B$12)+(1-Model!C15)*(IF(Inputs!$B$42="soc",INDEX(Inputs!$A$37:$C$37,1,2)*(Inputs!$B$25/14)*Inputs!$B$12,VLOOKUP(Inputs!$B$40,Inputs!$A$29:$K$33,10,FALSE())*(Inputs!$B$25/14)*Inputs!$B$12)))+IF(Model!B16,Model!C16*(VLOOKUP(Inputs!$B$40,Inputs!$A$29:$K$33,4,FALSE())*(Inputs!$B$25/14)*Inputs!$B$12)+(1-Model!C16)*(VLOOKUP(Inputs!$B$40,Inputs!$A$29:$K$33,7,FALSE())*(Inputs!$B$25/14)*Inputs!$B$12),Model!C16*(VLOOKUP(Inputs!$B$40,Inputs!$A$29:$K$33,4,FALSE())*(Inputs!$B$25/14)*Inputs!$B$12)+(1-Model!C16)*(IF(Inputs!$B$42="soc",INDEX(Inputs!$A$37:$C$37,1,2)*(Inputs!$B$25/14)*Inputs!$B$12,VLOOKUP(Inputs!$B$40,Inputs!$A$29:$K$33,10,FALSE())*(Inputs!$B$25/14)*Inputs!$B$12)))+IF(Model!B17,Model!C17*(VLOOKUP(Inputs!$B$40,Inputs!$A$29:$K$33,4,FALSE())*(Inputs!$B$25/14)*Inputs!$B$12)+(1-Model!C17)*(VLOOKUP(Inputs!$B$40,Inputs!$A$29:$K$33,7,FALSE())*(Inputs!$B$25/14)*Inputs!$B$12),Model!C17*(VLOOKUP(Inputs!$B$40,Inputs!$A$29:$K$33,4,FALSE())*(Inputs!$B$25/14)*Inputs!$B$12)+(1-Model!C17)*(IF(Inputs!$B$42="soc",INDEX(Inputs!$A$37:$C$37,1,2)*(Inputs!$B$25/14)*Inputs!$B$12,VLOOKUP(Inputs!$B$40,Inputs!$A$29:$K$33,10,FALSE())*(Inputs!$B$25/14)*Inputs!$B$12)))+IF(Model!B18,Model!C18*(VLOOKUP(Inputs!$B$40,Inputs!$A$29:$K$33,4,FALSE())*(Inputs!$B$25/14)*Inputs!$B$12)+(1-Model!C18)*(VLOOKUP(Inputs!$B$40,Inputs!$A$29:$K$33,7,FALSE())*(Inputs!$B$25/14)*Inputs!$B$12),Model!C18*(VLOOKUP(Inputs!$B$40,Inputs!$A$29:$K$33,4,FALSE())*(Inputs!$B$25/14)*Inputs!$B$12)+(1-Model!C18)*(IF(Inputs!$B$42="soc",INDEX(Inputs!$A$37:$C$37,1,2)*(Inputs!$B$25/14)*Inputs!$B$12,VLOOKUP(Inputs!$B$40,Inputs!$A$29:$K$33,10,FALSE())*(Inputs!$B$25/14)*Inputs!$B$12)))+IF(Model!B19,Model!C19*(VLOOKUP(Inputs!$B$40,Inputs!$A$29:$K$33,4,FALSE())*(Inputs!$B$25/14)*Inputs!$B$12)+(1-Model!C19)*(VLOOKUP(Inputs!$B$40,Inputs!$A$29:$K$33,7,FALSE())*(Inputs!$B$25/14)*Inputs!$B$12),Model!C19*(VLOOKUP(Inputs!$B$40,Inputs!$A$29:$K$33,4,FALSE())*(Inputs!$B$25/14)*Inputs!$B$12)+(1-Model!C19)*(IF(Inputs!$B$42="soc",INDEX(Inputs!$A$37:$C$37,1,2)*(Inputs!$B$25/14)*Inputs!$B$12,VLOOKUP(Inputs!$B$40,Inputs!$A$29:$K$33,10,FALSE())*(Inputs!$B$25/14)*Inputs!$B$12)))+IF(Model!B20,Model!C20*(VLOOKUP(Inputs!$B$40,Inputs!$A$29:$K$33,4,FALSE())*(Inputs!$B$25/14)*Inputs!$B$12)+(1-Model!C20)*(VLOOKUP(Inputs!$B$40,Inputs!$A$29:$K$33,7,FALSE())*(Inputs!$B$25/14)*Inputs!$B$12),Model!C20*(VLOOKUP(Inputs!$B$40,Inputs!$A$29:$K$33,4,FALSE())*(Inputs!$B$25/14)*Inputs!$B$12)+(1-Model!C20)*(IF(Inputs!$B$42="soc",INDEX(Inputs!$A$37:$C$37,1,2)*(Inputs!$B$25/14)*Inputs!$B$12,VLOOKUP(Inputs!$B$40,Inputs!$A$29:$K$33,10,FALSE())*(Inputs!$B$25/14)*Inputs!$B$12))) -> 2586.5262 | C14: =Model!E9*(VLOOKUP(Inputs!$B$40,Inputs!$A$29:$K$33,4,FALSE())*(Inputs!$B$25/14)*Inputs!$B$12)+(1-Model!E9)*(INDEX(Inputs!$A$37:$C$37,1,2)*(Inputs!$B$25/14)*Inputs!$B$12)+INDEX(Inputs!$A$37:$C$37,1,2)*(Inputs!$B$25/14)*Inputs!$B$12+INDEX(Inputs!$A$37:$C$37,1,2)*(Inputs!$B$25/14)*Inputs!$B$12+INDEX(Inputs!$A$37:$C$37,1,2)*(Inputs!$B$25/14)*Inputs!$B$12+INDEX(Inputs!$A$37:$C$37,1,2)*(Inputs!$B$25/14)*Inputs!$B$12+INDEX(Inputs!$A$37:$C$37,1,2)*(Inputs!$B$25/14)*Inputs!$B$12+INDEX(Inputs!$A$37:$C$37,1,2)*(Inputs!$B$25/14)*Inputs!$B$12+INDEX(Inputs!$A$37:$C$37,1,2)*(Inputs!$B$25/14)*Inputs!$B$12+INDEX(Inputs!$A$37:$C$37,1,2)*(Inputs!$B$25/14)*Inputs!$B$12+INDEX(Inputs!$A$37:$C$37,1,2)*(Inputs!$B$25/14)*Inputs!$B$12+INDEX(Inputs!$A$37:$C$37,1,2)*(Inputs!$B$25/14)*Inputs!$B$12+INDEX(Inputs!$A$37:$C$37,1,2)*(Inputs!$B$25/14)*Inputs!$B$12 -> 3518.4514 | D14: =B14-C14 -> -931.92521 | E14: 2577.39 / 3505.53 (-928.13)
A15: Oxygen | B15: =IF(Model!B9,Model!C9*(VLOOKUP(Inputs!$B$40,Inputs!$A$29:$K$33,5,FALSE())*(Inputs!$B$25/14)*Inputs!$B$13)+(1-Model!C9)*(VLOOKUP(Inputs!$B$40,Inputs!$A$29:$K$33,8,FALSE())*(Inputs!$B$25/14)*Inputs!$B$13),Model!C9*(VLOOKUP(Inputs!$B$40,Inputs!$A$29:$K$33,5,FALSE())*(Inputs!$B$25/14)*Inputs!$B$13)+(1-Model!C9)*(IF(Inputs!$B$42="soc",INDEX(Inputs!$A$37:$C$37,1,3)*(Inputs!$B$25/14)*Inputs!$B$13,VLOOKUP(Inputs!$B$40,Inputs!$A$29:$K$33,11,FALSE())*(Inputs!$B$25/14)*Inputs!$B$13)))+IF(Model!B10,Model!C10*(VLOOKUP(Inputs!$B$40,Inputs!$A$29:$K$33,5,FALSE())*(Inputs!$B$25/14)*Inputs!$B$13)+(1-Model!C10)*(VLOOKUP(Inputs!$B$40,Inputs!$A$29:$K$33,8,FALSE())*(Inputs!$B$25/14)*Inputs!$B$13),Model!C10*(VLOOKUP(Inputs!$B$40,Inputs!$A$29:$K$33,5,FALSE())*(Inputs!$B$25/14)*Inputs!$B$13)+(1-Model!C10)*(IF(Inputs!$B$42="soc",INDEX(Inputs!$A$37:$C$37,1,3)*(Inputs!$B$25/14)*Inputs!$B$13,VLOOKUP(Inputs!$B$40,Inputs!$A$29:$K$33,11,FALSE())*(Inputs!$B$25/14)*Inputs!$B$13)))+IF(Model!B11,Model!C11*(VLOOKUP(Inputs!$B$40,Inputs!$A$29:$K$33,5,FALSE())*(Inputs!$B$25/14)*Inputs!$B$13)+(1-Model!C11)*(VLOOKUP(Inputs!$B$40,Inputs!$A$29:$K$33,8,FALSE())*(Inputs!$B$25/14)*Inputs!$B$13),Model!C11*(VLOOKUP(Inputs!$B$40,Inputs!$A$29:$K$33,5,FALSE())*(Inputs!$B$25/14)*Inputs!$B$13)+(1-Model!C11)*(IF(Inputs!$B$42="soc",INDEX(Inputs!$A$37:$C$37,1,3)*(Inputs!$B$25/14)*Inputs!$B$13,VLOOKUP(Inputs!$B$40,Inputs!$A$29:$K$33,11,FALSE())*(Inputs!$B$25/14)*Inputs!$B$13)))+IF(Model!B12,Model!C12*(VLOOKUP(Inputs!$B$40,Inputs!$A$29:$K$33,5,FALSE())*(Inputs!$B$25/14)*Inputs!$B$13)+(1-Model!C12)*(VLOOKUP(Inputs!$B$40,Inputs!$A$29:$K$33,8,FALSE())*(Inputs!$B$25/14)*Inputs!$B$13),Model!C12*(VLOOKUP(Inputs!$B$40,Inputs!$A$29:$K$33,5,FALSE())*(Inputs!$B$25/14)*Inputs!$B$13)+(1-Model!C12)*(IF(Inputs!$B$42="soc",INDEX(Inputs!$A$37:$C$37,1,3)*(Inputs!$B$25/14)*Inputs!$B$13,VLOOKUP(Inputs!$B$40,Inputs!$A$29:$K$33,11,FALSE())*(Inputs!$B$25/14)*Inputs!$B$13)))+IF(Model!B13,Model!C13*(VLOOKUP(Inputs!$B$40,Inputs!$A$29:$K$33,5,FALSE())*(Inputs!$B$25/14)*Inputs!$B$13)+(1-Model!C13)*(VLOOKUP(Inputs!$B$40,Inputs!$A$29:$K$33,8,FALSE())*(Inputs!$B$25/14)*Inputs!$B$13),Model!C13*(VLOOKUP(Inputs!$B$40,Inputs!$A$29:$K$33,5,FALSE())*(Inputs!$B$25/14)*Inputs!$B$13)+(1-Model!C13)*(IF(Inputs!$B$42="soc",INDEX(Inputs!$A$37:$C$37,1,3)*(Inputs!$B$25/14)*Inputs!$B$13,VLOOKUP(Inputs!$B$40,Inputs!$A$29:$K$33,11,FALSE())*(Inputs!$B$25/14)*Inputs!$B$13)))+IF(Model!B14,Model!C14*(VLOOKUP(Inputs!$B$40,Inputs!$A$29:$K$33,5,FALSE())*(Inputs!$B$25/14)*Inputs!$B$13)+(1-Model!C14)*(VLOOKUP(Inputs!$B$40,Inputs!$A$29:$K$33,8,FALSE())*(Inputs!$B$25/14)*Inputs!$B$13),Model!C14*(VLOOKUP(Inputs!$B$40,Inputs!$A$29:$K$33,5,FALSE())*(Inputs!$B$25/14)*Inputs!$B$13)+(1-Model!C14)*(IF(Inputs!$B$42="soc",INDEX(Inputs!$A$37:$C$37,1,3)*(Inputs!$B$25/14)*Inputs!$B$13,VLOOKUP(Inputs!$B$40,Inputs!$A$29:$K$33,11,FALSE())*(Inputs!$B$25/14)*Inputs!$B$13)))+IF(Model!B15,Model!C15*(VLOOKUP(Inputs!$B$40,Inputs!$A$29:$K$33,5,FALSE())*(Inputs!$B$25/14)*Inputs!$B$13)+(1-Model!C15)*(VLOOKUP(Inputs!$B$40,Inputs!$A$29:$K$33,8,FALSE())*(Inputs!$B$25/14)*Inputs!$B$13),Model!C15*(VLOOKUP(Inputs!$B$40,Inputs!$A$29:$K$33,5,FALSE())*(Inputs!$B$25/14)*Inputs!$B$13)+(1-Model!C15)*(IF(Inputs!$B$42="soc",INDEX(Inputs!$A$37:$C$37,1,3)*(Inputs!$B$25/14)*Inputs!$B$13,VLOOKUP(Inputs!$B$40,Inputs!$A$29:$K$33,11,FALSE())*(Inputs!$B$25/14)*Inputs!$B$13)))+IF(Model!B16,Model!C16*(VLOOKUP(Inputs!$B$40,Inputs!$A$29:$K$33,5,FALSE())*(Inputs!$B$25/14)*Inputs!$B$13)+(1-Model!C16)*(VLOOKUP(Inputs!$B$40,Inputs!$A$29:$K$33,8,FALSE())*(Inputs!$B$25/14)*Inputs!$B$13),Model!C16*(VLOOKUP(Inputs!$B$40,Inputs!$A$29:$K$33,5,FALSE())*(Inputs!$B$25/14)*Inputs!$B$13)+(1-Model!C16)*(IF(Inputs!$B$42="soc",INDEX(Inputs!$A$37:$C$37,1,3)*(Inputs!$B$25/14)*Inputs!$B$13,VLOOKUP(Inputs!$B$40,Inputs!$A$29:$K$33,11,FALSE())*(Inputs!$B$25/14)*Inputs!$B$13)))+IF(Model!B17,Model!C17*(VLOOKUP(Inputs!$B$40,Inputs!$A$29:$K$33,5,FALSE())*(Inputs!$B$25/14)*Inputs!$B$13)+(1-Model!C17)*(VLOOKUP(Inputs!$B$40,Inputs!$A$29:$K$33,8,FALSE())*(Inputs!$B$25/14)*Inputs!$B$13),Model!C17*(VLOOKUP(Inputs!$B$40,Inputs!$A$29:$K$33,5,FALSE())*(Inputs!$B$25/14)*Inputs!$B$13)+(1-Model!C17)*(IF(Inputs!$B$42="soc",INDEX(Inputs!$A$37:$C$37,1,3)*(Inputs!$B$25/14)*Inputs!$B$13,VLOOKUP(Inputs!$B$40,Inputs!$A$29:$K$33,11,FALSE())*(Inputs!$B$25/14)*Inputs!$B$13)))+IF(Model!B18,Model!C18*(VLOOKUP(Inputs!$B$40,Inputs!$A$29:$K$33,5,FALSE())*(Inputs!$B$25/14)*Inputs!$B$13)+(1-Model!C18)*(VLOOKUP(Inputs!$B$40,Inputs!$A$29:$K$33,8,FALSE())*(Inputs!$B$25/14)*Inputs!$B$13),Model!C18*(VLOOKUP(Inputs!$B$40,Inputs!$A$29:$K$33,5,FALSE())*(Inputs!$B$25/14)*Inputs!$B$13)+(1-Model!C18)*(IF(Inputs!$B$42="soc",INDEX(Inputs!$A$37:$C$37,1,3)*(Inputs!$B$25/14)*Inputs!$B$13,VLOOKUP(Inputs!$B$40,Inputs!$A$29:$K$33,11,FALSE())*(Inputs!$B$25/14)*Inputs!$B$13)))+IF(Model!B19,Model!C19*(VLOOKUP(Inputs!$B$40,Inputs!$A$29:$K$33,5,FALSE())*(Inputs!$B$25/14)*Inputs!$B$13)+(1-Model!C19)*(VLOOKUP(Inputs!$B$40,Inputs!$A$29:$K$33,8,FALSE())*(Inputs!$B$25/14)*Inputs!$B$13),Model!C19*(VLOOKUP(Inputs!$B$40,Inputs!$A$29:$K$33,5,FALSE())*(Inputs!$B$25/14)*Inputs!$B$13)+(1-Model!C19)*(IF(Inputs!$B$42="soc",INDEX(Inputs!$A$37:$C$37,1,3)*(Inputs!$B$25/14)*Inputs!$B$13,VLOOKUP(Inputs!$B$40,Inputs!$A$29:$K$33,11,FALSE())*(Inputs!$B$25/14)*Inputs!$B$13)))+IF(Model!B20,Model!C20*(VLOOKUP(Inputs!$B$40,Inputs!$A$29:$K$33,5,FALSE())*(Inputs!$B$25/14)*Inputs!$B$13)+(1-Model!C20)*(VLOOKUP(Inputs!$B$40,Inputs!$A$29:$K$33,8,FALSE())*(Inputs!$B$25/14)*Inputs!$B$13),Model!C20*(VLOOKUP(Inputs!$B$40,Inputs!$A$29:$K$33,5,FALSE())*(Inputs!$B$25/14)*Inputs!$B$13)+(1-Model!C20)*(IF(Inputs!$B$42="soc",INDEX(Inputs!$A$37:$C$37,1,3)*(Inputs!$B$25/14)*Inputs!$B$13,VLOOKUP(Inputs!$B$40,Inputs!$A$29:$K$33,11,FALSE())*(Inputs!$B$25/14)*Inputs!$B$13))) -> 148.02839 | C15: =Model!E9*(VLOOKUP(Inputs!$B$40,Inputs!$A$29:$K$33,5,FALSE())*(Inputs!$B$25/14)*Inputs!$B$13)+(1-Model!E9)*(INDEX(Inputs!$A$37:$C$37,1,3)*(Inputs!$B$25/14)*Inputs!$B$13)+INDEX(Inputs!$A$37:$C$37,1,3)*(Inputs!$B$25/14)*Inputs!$B$13+INDEX(Inputs!$A$37:$C$37,1,3)*(Inputs!$B$25/14)*Inputs!$B$13+INDEX(Inputs!$A$37:$C$37,1,3)*(Inputs!$B$25/14)*Inputs!$B$13+INDEX(Inputs!$A$37:$C$37,1,3)*(Inputs!$B$25/14)*Inputs!$B$13+INDEX(Inputs!$A$37:$C$37,1,3)*(Inputs!$B$25/14)*Inputs!$B$13+INDEX(Inputs!$A$37:$C$37,1,3)*(Inputs!$B$25/14)*Inputs!$B$13+INDEX(Inputs!$A$37:$C$37,1,3)*(Inputs!$B$25/14)*Inputs!$B$13+INDEX(Inputs!$A$37:$C$37,1,3)*(Inputs!$B$25/14)*Inputs!$B$13+INDEX(Inputs!$A$37:$C$37,1,3)*(Inputs!$B$25/14)*Inputs!$B$13+INDEX(Inputs!$A$37:$C$37,1,3)*(Inputs!$B$25/14)*Inputs!$B$13+INDEX(Inputs!$A$37:$C$37,1,3)*(Inputs!$B$25/14)*Inputs!$B$13 -> 189.14338 | D15: =B15-C15 -> -41.114986 | E15: 147.55 / 188.49 (-40.95)
A16: Total | B16: =SUM(B12:B15) -> 3458.957 | C16: =SUM(C12:C15) -> 3913.0365 | D16: =B16-C16 -> -454.07954
A18: NOTES ON VALIDATION
A19: This replication reproduces the company's base-case total costs (Table C16) to within ~1%.
A20: The residual gap arises because Table C10 rounds resource-use inputs to 2–3 significant figures; the unrounded PREVA
A21: post-hoc data (referenced in the EAC report's correspondence log) is not published in this submission.
A22: Change the yellow selector cells on the Inputs sheet to explore the alternative response-definition and scenario
A23: assumptions described in Sections 9.4.1 and 9.4.3, or see the Scenarios and OWSA sheets for the full pre-computed grids.

Sheet Scenarios
A1: gammaCore for Chronic Cluster Headache — MULTI-WAY SCENARIO ANALYSIS (cf. Table C20)
A2: Each scenario below is a fully self-contained 12-month calculation (not linked to the Inputs selectors), so all 30 combinations are visible at once.
A4: SUMMARY TABLE
A5: Responder def. | B5: Loss assumption | C5: Non-resp. use | D5: gammaCore+SoC (£) | E5: SoC (£) | F5: Difference (£) | G5: Published (£)
A6: 25 | B6: none | C6: soc | D6: =D53 -> 3565.4536 | E6: =F53 -> 3913.4143 | F6: =D53-F53 -> -347.96069 | G6: -343
A7: 25 | B7: none | C7: baseline | D7: =D69 -> 3085.619 | E7: =F69 -> 3913.4143 | F7: =D69-F69 -> -827.79528 | G7: -821
A8: 25 | B8: constant | C8: soc | D8: =D85 -> 3606.2651 | E8: =F85 -> 3913.4143 | F8: =D85-F85 -> -307.14921 | G8: -256
A9: 25 | B9: constant | C9: baseline | D9: =D101 -> 2843.2319 | E9: =F101 -> 3913.4143 | F9: =D101-F101 -> -1070.1824
A10: 25 | B10: diminishing | C10: soc | D10: =D117 -> 3601.7464 | E10: =F117 -> 3913.4143 | F10: =D117-F117 -> -311.66793
A11: 25 | B11: diminishing | C11: baseline | D11: =D133 -> 2874.4549 | E11: =F133 -> 3913.4143 | F11: =D133-F133 -> -1038.9594
A12: 40 | B12: none | C12: soc | D12: =D149 -> 3515.1815 | E12: =F149 -> 3915.1784 | F12: =D149-F149 -> -399.99685 | G12: -394
A13: 40 | B13: none | C13: baseline | D13: =D165 -> 2653.1333 | E13: =F165 -> 3915.1784 | F13: =D165-F165 -> -1262.0451 | G13: -1256
A14: 40 | B14: constant | C14: soc | D14: =D181 -> 3482.581 | E14: =F181 -> 3915.1784 | F14: =D181-F181 -> -432.59741
A15: 40 | B15: constant | C15: baseline | D15: =D197 -> 2274.8947 | E15: =F197 -> 3915.1784 | F15: =D197-F197 -> -1640.2837
A16: 40 | B16: diminishing | C16: soc | D16: =D213 -> 3486.8564 | E16: =F213 -> 3915.1784 | F16: =D213-F213 -> -428.32196
A17: 40 | B17: diminishing | C17: baseline | D17: =D229 -> 2322.7922 | E17: =F229 -> 3915.1784 | F17: =D229-F229 -> -1592.3862
A18: 50m | B18: none | C18: soc | D18: =D245 -> 3806.3346 | E18: =F245 -> 3915.6354 | F18: =D245-F245 -> -109.30078 | G18: -104
A19: 50m | B19: none | C19: baseline | D19: =D261 -> 3806.3346 | E19: =F261 -> 3915.6354 | F19: =D261-F261 -> -109.30078 | G19: -104
A20: 50m | B20: constant | C20: soc | D20: =D277 -> 3777.9291 | E20: =F277 -> 3915.6354 | F20: =D277-F277 -> -137.70629 | G20: -101
A21: 50m | B21: constant | C21: baseline | D21: =D293 -> 3777.9291 | E21: =F293 -> 3915.6354 | F21: =D293-F293 -> -137.70629
A22: 50m | B22: diminishing | C22: soc | D22: =D309 -> 3781.9332 | E22: =F309 -> 3915.6354 | F22: =D309-F309 -> -133.70214
A23: 50m | B23: diminishing | C23: baseline | D23: =D325 -> 3781.9332 | E23: =F325 -> 3915.6354 | F23: =D325-F325 -> -133.70214
A24: 50 | B24: none | C24: soc | D24: =D341 -> 3458.957 | E24: =F341 -> 3913.0365 | F24: =D341-F341 -> -454.07954 | G24: -450
A25: 50 | B25: none | C25: baseline | D25: =D357 -> 2981.1262 | E25: =F357 -> 3913.0365 | F25: =D357-F357 -> -931.91031 | G25: -926
A26: 50 | B26: constant | C26: soc | D26: =D373 -> 3488.1884 | E26: =F373 -> 3913.0365 | F26: =D373-F373 -> -424.84816 | G26: -390
A27: 50 | B27: constant | C27: baseline | D27: =D389 -> 2858.1833 | E27: =F389 -> 3913.0365 | F27: =D389-F389 -> -1054.8533
A28: 50 | B28: diminishing | C28: soc | D28: =D405 -> 3484.726 | E28: =F405 -> 3913.0365 | F28: =D405-F405 -> -428.31054
A29: 50 | B29: diminishing | C29: baseline | D29: =D421 -> 2873.9264 | E29: =F421 -> 3913.0365 | F29: =D421-F421 -> -1039.1102
A30: 65 | B30: none | C30: soc | D30: =D437 -> 3400.5806 | E30: =F437 -> 3910.5656 | F30: =D437-F437 -> -509.98508 | G30: -512
A31: 65 | B31: none | C31: baseline | D31: =D453 -> 3134.0113 | E31: =F453 -> 3910.5656 | F31: =D453-F453 -> -776.55437 | G31: -776
A32: 65 | B32: constant | C32: soc | D32: =D469 -> 3455.7547 | E32: =F469 -> 3910.5656 | F32: =D469-F469 -> -454.81095 | G32: -437
A33: 65 | B33: constant | C33: baseline | D33: =D485 -> 3144.9884 | E33: =F485 -> 3910.5656 | F33: =D485-F485 -> -765.57727
A34: 65 | B34: diminishing | C34: soc | D34: =D501 -> 3448.9423 | E34: =F501 -> 3910.5656 | F34: =D501-F501 -> -461.6233
A35: 65 | B35: diminishing | C35: baseline | D35: =D517 -> 3143.754 | E35: =F517 -> 3910.5656 | F35: =D517-F517 -> -766.81164
A37: DETAIL CALCULATIONS (one 12-month block per scenario)
A39: Scenario: 25% / none / non-resp use = soc
A40: Cycle | B40: Free trial? | C40: gCore resp % | D40: gCore cost (£) | E40: SoC resp % | F40: SoC cost (£)
A41: 1 | B41: =A41<=Inputs!$B$17 -> TRUE | C41: =VLOOKUP("25",Inputs!$A$29:$K$33,2,FALSE()) -> 0.6 | D41: =IF(B41,C41*(VLOOKUP("25",Inputs!$A$29:$K$33,3,FALSE())*(Inputs!$B$25/14)*Inputs!$B$5+VLOOKUP("25",Inputs!$A$29:$K$33,4,FALSE())*(Inputs!$B$25/14)*Inputs!$B$12+VLOOKUP("25",Inputs!$A$29:$K$33,5,FALSE())*(Inputs!$B$25/14)*Inputs!$B$13)+(1-C41)*(VLOOKUP("25",Inputs!$A$29:$K$33,6,FALSE())*(Inputs!$B$25/14)*Inputs!$B$5+VLOOKUP("25",Inputs!$A$29:$K$33,7,FALSE())*(Inputs!$B$25/14)*Inputs!$B$12+VLOOKUP("25",Inputs!$A$29:$K$33,8,FALSE())*(Inputs!$B$25/14)*Inputs!$B$13),C41*((VLOOKUP("25",Inputs!$A$29:$K$33,3,FALSE())*(Inputs!$B$25/14)*Inputs!$B$5+VLOOKUP("25",Inputs!$A$29:$K$33,4,FALSE())*(Inputs!$B$25/14)*Inputs!$B$12+VLOOKUP("25",Inputs!$A$29:$K$33,5,FALSE())*(Inputs!$B$25/14)*Inputs!$B$13)+Inputs!$B$18)+(1-C41)*((INDEX(Inputs!$A$37:$C$37,1,1)*(Inputs!$B$25/14)*Inputs!$B$5+INDEX(Inputs!$A$37:$C$37,1,2)*(Inputs!$B$25/14)*Inputs!$B$12+INDEX(Inputs!$A$37:$C$37,1,3)*(Inputs!$B$25/14)*Inputs!$B$13))) -> 189.05901 | E41: =Inputs!$B$21 -> 0.083 | F41: =E41*(VLOOKUP("25",Inputs!$A$29:$K$33,3,FALSE())*(Inputs!$B$25/14)*Inputs!$B$5+VLOOKUP("25",Inputs!$A$29:$K$33,4,FALSE())*(Inputs!$B$25/14)*Inputs!$B$12+VLOOKUP("25",Inputs!$A$29:$K$33,5,FALSE())*(Inputs!$B$25/14)*Inputs!$B$13)+(1-E41)*(INDEX(Inputs!$A$37:$C$37,1,1)*(Inputs!$B$25/14)*Inputs!$B$5+INDEX(Inputs!$A$37:$C$37,1,2)*(Inputs!$B$25/14)*Inputs!$B$12+INDEX(Inputs!$A$37:$C$37,1,3)*(Inputs!$B$25/14)*Inputs!$B$13) -> 309.85906
A42: 2 | B42: =A42<=Inputs!$B$17 -> TRUE | C42: =IF(A42=2,C41*(1-Inputs!$B$22),C41) -> 0.414 | D42: =IF(B42,C42*(VLOOKUP("25",Inputs!$A$29:$K$33,3,FALSE())*(Inputs!$B$25/14)*Inputs!$B$5+VLOOKUP("25",Inputs!$A$29:$K$33,4,FALSE())*(Inputs!$B$25/14)*Inputs!$B$12+VLOOKUP("25",Inputs!$A$29:$K$33,5,FALSE())*(Inputs!$B$25/14)*Inputs!$B$13)+(1-C42)*(VLOOKUP("25",Inputs!$A$29:$K$33,6,FALSE())*(Inputs!$B$25/14)*Inputs!$B$5+VLOOKUP("25",Inputs!$A$29:$K$33,7,FALSE())*(Inputs!$B$25/14)*Inputs!$B$12+VLOOKUP("25",Inputs!$A$29:$K$33,8,FALSE())*(Inputs!$B$25/14)*Inputs!$B$13),C42*((VLOOKUP("25",Inputs!$A$29:$K$33,3,FALSE())*(Inputs!$B$25/14)*Inputs!$B$5+VLOOKUP("25",Inputs!$A$29:$K$33,4,FALSE())*(Inputs!$B$25/14)*Inputs!$B$12+VLOOKUP("25",Inputs!$A$29:$K$33,5,FALSE())*(Inputs!$B$25/14)*Inputs!$B$13)+Inputs!$B$18)+(1-C42)*((INDEX(Inputs!$A$37:$C$37,1,1)*(Inputs!$B$25/14)*Inputs!$B$5+INDEX(Inputs!$A$37:$C$37,1,2)*(Inputs!$B$25/14)*Inputs!$B$12+INDEX(Inputs!$A$37:$C$37,1,3)*(Inputs!$B$25/14)*Inputs!$B$13))) -> 224.00855 | E42: =0 -> 0 | F42: =(INDEX(Inputs!$A$37:$C$37,1,1)*(Inputs!$B$25/14)*Inputs!$B$5+INDEX(Inputs!$A$37:$C$37,1,2)*(Inputs!$B$25/14)*Inputs!$B$12+INDEX(Inputs!$A$37:$C$37,1,3)*(Inputs!$B$25/14)*Inputs!$B$13) -> 327.59593
A43: 3 | B43: =A43<=Inputs!$B$17 -> TRUE | C43: =IF(A43=2,C42*(1-Inputs!$B$22),C42) -> 0.414 | D43: =IF(B43,C43*(VLOOKUP("25",Inputs!$A$29:$K$33,3,FALSE())*(Inputs!$B$25/14)*Inputs!$B$5+VLOOKUP("25",Inputs!$A$29:$K$33,4,FALSE())*(Inputs!$B$25/14)*Inputs!$B$12+VLOOKUP("25",Inputs!$A$29:$K$33,5,FALSE())*(Inputs!$B$25/14)*Inputs!$B$13)+(1-C43)*(VLOOKUP("25",Inputs!$A$29:$K$33,6,FALSE())*(Inputs!$B$25/14)*Inputs!$B$5+VLOOKUP("25",Inputs!$A$29:$K$33,7,FALSE())*(Inputs!$B$25/14)*Inputs!$B$12+VLOOKUP("25",Inputs!$A$29:$K$33,8,FALSE())*(Inputs!$B$25/14)*Inputs!$B$13),C43*((VLOOKUP("25",Inputs!$A$29:$K$33,3,FALSE())*(Inputs!$B$25/14)*Inputs!$B$5+VLOOKUP("25",Inputs!$A$29:$K$33,4,FALSE())*(Inputs!$B$25/14)*Inputs!$B$12+VLOOKUP("25",Inputs!$A$29:$K$33,5,FALSE())*(Inputs!$B$25/14)*Inputs!$B$13)+Inputs!$B$18)+(1-C43)*((INDEX(Inputs!$A$37:$C$37,1,1)*(Inputs!$B$25/14)*Inputs!$B$5+INDEX(Inputs!$A$37:$C$37,1,2)*(Inputs!$B$25/14)*Inputs!$B$12+INDEX(Inputs!$A$37:$C$37,1,3)*(Inputs!$B$25/14)*Inputs!$B$13))) -> 224.00855 | E43: =0 -> 0 | F43: =(INDEX(Inputs!$A$37:$C$37,1,1)*(Inputs!$B$25/14)*Inputs!$B$5+INDEX(Inputs!$A$37:$C$37,1,2)*(Inputs!$B$25/14)*Inputs!$B$12+INDEX(Inputs!$A$37:$C$37,1,3)*(Inputs!$B$25/14)*Inputs!$B$13) -> 327.59593
...

Sheet OWSA
A1: gammaCore for Chronic Cluster Headache — ONE-WAY SENSITIVITY ANALYSIS (cf. Table C19)
A2: Base case (50% definition, no response loss, SoC non-responder use). Each parameter is varied to its lower/upper bound (Table C13) while all others are held at base case.
A4: TORNADO SUMMARY
A5: Parameter | B5: Base | C5: Lower bound | D5: Upper bound | E5: Cost diff @ lower (£) | F5: Cost diff @ upper (£) | G5: Range (£)
A6: Sumatriptan doses/14d — SoC non-responder | B6: 7.5 | C6: 4.88 | D6: 10.67 | E6: =OWSA!D33 -> 101.68615 | F6: =OWSA!D49 -> -1126.5136 | G6: =ABS(F6-E6) -> 1228.1998
A7: Sumatriptan doses/14d — gCore non-resp. (on Tx) | B7: 4.1 | C7: 1 | D7: 9.33 | E7: =OWSA!D65 -> -703.4287 | F7: =OWSA!D81 -> -33.403376 | G7: =ABS(F7-E7) -> 670.02532
A8: Sumatriptan doses/14d — gCore responder | B8: 2.5 | C8: 1.04 | D8: 4.59 | E8: =OWSA!D97 -> -646.34562 | F8: =OWSA!D113 -> -178.84933 | G8: =ABS(F8-E8) -> 467.49629
A9: % sumatriptan treatments that are s.c. | B9: 0.867 | C9: 0.661 | D9: 0.982 | E9: =OWSA!D129 -> -319.43474 | F9: =OWSA!D145 -> -529.24532 | G9: =ABS(F9-E9) -> 209.81058
A10: Zolmitriptan doses/14d — gCore non-resp. (on Tx) | B10: 2.5 | C10: 0.32 | D10: 6.89 | E10: =OWSA!D161 -> -513.0957 | F10: =OWSA!D177 -> -335.23507 | G10: =ABS(F10-E10) -> 177.86064
A11: Zolmitriptan doses/14d — SoC non-responder | B11: 1.3 | C11: 0.45 | D11: 2.59 | E11: =OWSA!D193 -> -393.39506 | F11: =OWSA!D209 -> -546.17716 | G11: =ABS(F11-E11) -> 152.7821
A12: Probability of response — gCore (50% def.) | B12: 0.4 | C12: 0.263 | D12: 0.545 | E12: =OWSA!D225 -> -412.65862 | F12: =OWSA!D241 -> -497.9192 | G12: =ABS(F12-E12) -> 85.260587
